<?xml version="1.0" ?>
<!-- =================================================================================== -->
<!-- |    This document was autogenerated by xacro from dual_ur5_ft_gripper_base.urdf.xacro | -->
<!-- |    EDITING THIS FILE BY HAND IS NOT RECOMMENDED                                 | -->
<!-- =================================================================================== -->
<robot name="dual_ur5_ft_gripper_base">
  <link name="world"/>
  <link name="plane_collision">
    <visual>
      <origin rpy="0.0 0 0" xyz="0 0 -0.02"/>
      <geometry>
        <mesh filename="file:///home/jjmczd/dual_v10/install/dual_description/share/dual_description/meshes/plane_collision.stl" scale="2 2 2"/>
      </geometry>
      <material name="white">
        <color rgba="1 1 1 1"/>
      </material>
    </visual>
    <collision>
      <origin rpy="0 0 0" xyz="0 0 -0.02"/>
      <geometry>
        <mesh filename="file:///home/jjmczd/dual_v10/install/dual_description/share/dual_description/meshes/plane_collision.stl" scale="2 2 2"/>
      </geometry>
    </collision>
  </link>
  <joint name="plane_joint" type="fixed">
    <parent link="world"/>
    <child link="plane_collision"/>
    <origin rpy="0 0 0" xyz="0 0 0"/>
  </joint>
  <link name="dual_base">
    <visual>
      <origin rpy="0.0 0 0" xyz="0 0 0"/>
      <geometry>
        <mesh filename="file:///home/jjmczd/dual_v10/install/dual_description/share/dual_description/meshes/dual_base.stl"/>
      </geometry>
      <material name="blue">
        <color rgba="0 0 1.0 1"/>
      </material>
    </visual>
    <collision>
      <origin rpy="0 0 0" xyz="0 0 0"/>
      <geometry>
        <mesh filename="file:///home/jjmczd/dual_v10/install/dual_description/share/dual_description/meshes/dual_base.stl"/>
      </geometry>
    </collision>
    <!-- 双臂基座台的惯性系数未知
      <inertial>
        <mass
        value="1" />
    	  <inertia ixx="0" ixy="0" ixz="0" iyy="0" iyz="0" izz="0"/>
      </inertial>
      -->
  </link>
  <joint name="world_dual_base_joint" type="fixed">
    <parent link="world"/>
    <child link="dual_base"/>
    <origin rpy="0 0 0" xyz="0 0 0"/>
  </joint>
  <!--
    Base UR robot series xacro macro.

    NOTE this is NOT a URDF. It cannot directly be loaded by consumers
    expecting a flattened '.urdf' file. See the top-level '.xacro' for that
    (but note that .xacro must still be processed by the xacro command).

    This file models the base kinematic chain of a UR robot, which then gets
    parameterised by various configuration files to convert it into a UR3(e),
    UR5(e), UR10(e) or UR16e.

    NOTE the default kinematic parameters (i.e., link lengths, frame locations,
    offsets, etc) do not correspond to any particular robot. They are defaults
    only. There WILL be non-zero offsets between the Forward Kinematics results
    in TF (i.e., robot_state_publisher) and the values reported by the Teach
    Pendant.

    For accurate (and robot-specific) transforms, the 'kinematics_parameters_file'
    parameter MUST point to a .yaml file containing the appropriate values for
    the targeted robot.

    If using the UniversalRobots/Universal_Robots_ROS_Driver, follow the steps
    described in the readme of that repository to extract the kinematic
    calibration from the controller and generate the required .yaml file.

    Main author of the migration to yaml configs Ludovic Delval.

    Contributors to previous versions (in no particular order)

     - Denis Stogl
     - Lovro Ivanov
     - Felix Messmer
     - Kelsey Hawkins
     - Wim Meeussen
     - Shaun Edwards
     - Nadia Hammoudeh Garcia
     - Dave Hershberger
     - G. vd. Hoorn
     - Philip Long
     - Dave Coleman
     - Miguel Prada
     - Mathias Luedtke
     - Marcel Schnirring
     - Felix von Drigalski
     - Felix Exner
     - Jimmy Da Silva
     - Ajit Krisshna N L
     - Muhammad Asif Rana
  -->
  <!--
    NOTE the macro defined in this file is NOT part of the public API of this
          package. Users CANNOT rely on this file being available, or stored in
          this location. Nor can they rely on the existence of the macro.
  -->
  <ros2_control name="left_ur" type="system">
    <hardware>
      <plugin>gazebo_ros2_control/GazeboSystem</plugin>
    </hardware>
    <joint name="left_shoulder_pan_joint">
      <command_interface name="position"/>
      <command_interface name="velocity"/>
      <state_interface name="position">
        <!-- initial position for the FakeSystem and simulation -->
        <param name="initial_value">1.09624</param>
      </state_interface>
      <state_interface name="velocity"/>
      <state_interface name="effort"/>
    </joint>
    <joint name="left_shoulder_lift_joint">
      <command_interface name="position"/>
      <command_interface name="velocity"/>
      <state_interface name="position">
        <!-- initial position for the FakeSystem and simulation -->
        <param name="initial_value">-2.44259</param>
      </state_interface>
      <state_interface name="velocity"/>
      <state_interface name="effort"/>
    </joint>
    <joint name="left_elbow_joint">
      <command_interface name="position"/>
      <command_interface name="velocity"/>
      <state_interface name="position">
        <!-- initial position for the FakeSystem and simulation -->
        <param name="initial_value">2.22879</param>
      </state_interface>
      <state_interface name="velocity"/>
      <state_interface name="effort"/>
    </joint>
    <joint name="left_wrist_1_joint">
      <command_interface name="position"/>
      <command_interface name="velocity"/>
      <state_interface name="position">
        <!-- initial position for the FakeSystem and simulation -->
        <param name="initial_value">-0.591143</param>
      </state_interface>
      <state_interface name="velocity"/>
      <state_interface name="effort"/>
    </joint>
    <joint name="left_wrist_2_joint">
      <command_interface name="position"/>
      <command_interface name="velocity"/>
      <state_interface name="position">
        <!-- initial position for the FakeSystem and simulation -->
        <param name="initial_value">1.74742</param>
      </state_interface>
      <state_interface name="velocity"/>
      <state_interface name="effort"/>
    </joint>
    <joint name="left_wrist_3_joint">
      <command_interface name="position"/>
      <command_interface name="velocity"/>
      <state_interface name="position">
        <!-- initial position for the FakeSystem and simulation -->
        <param name="initial_value">0.523774</param>
      </state_interface>
      <state_interface name="velocity"/>
      <state_interface name="effort"/>
    </joint>
  </ros2_control>
  <!-- Add URDF transmission elements (for ros_control) -->
  <!-- NOTE  delete colon （maohao）-->
  <!-- Placeholder for ros2_control transmission which don't yet exist -->
  <!-- links -  main serial chain -->
  <link name="left_base_link"/>
  <link name="left_base_link_inertia">
    <visual>
      <origin rpy="0 0 3.141592653589793" xyz="0 0 0"/>
      <geometry>
        <mesh filename="file:///opt/ros/humble/share/ur_description/meshes/ur5/visual/base.dae"/>
      </geometry>
    </visual>
    <collision>
      <origin rpy="0 0 3.141592653589793" xyz="0 0 0"/>
      <geometry>
        <mesh filename="file:///opt/ros/humble/share/ur_description/meshes/ur5/collision/base.stl"/>
      </geometry>
    </collision>
    <inertial>
      <mass value="4.0"/>
      <origin rpy="0 0 0" xyz="0 0 0"/>
      <inertia ixx="0.00443333156" ixy="0.0" ixz="0.0" iyy="0.00443333156" iyz="0.0" izz="0.0072"/>
    </inertial>
  </link>
  <link name="left_shoulder_link">
    <visual>
      <origin rpy="0 0 3.141592653589793" xyz="0 0 0"/>
      <geometry>
        <mesh filename="file:///opt/ros/humble/share/ur_description/meshes/ur5/visual/shoulder.dae"/>
      </geometry>
    </visual>
    <collision>
      <origin rpy="0 0 3.141592653589793" xyz="0 0 0"/>
      <geometry>
        <mesh filename="file:///opt/ros/humble/share/ur_description/meshes/ur5/collision/shoulder.stl"/>
      </geometry>
    </collision>
    <inertial>
      <mass value="3.7"/>
      <origin rpy="0 0 0" xyz="0 0 0"/>
      <inertia ixx="0.014972352344389999" ixy="0.0" ixz="0.0" iyy="0.014972352344389999" iyz="0.0" izz="0.01040625"/>
    </inertial>
  </link>
  <link name="left_upper_arm_link">
    <visual>
      <origin rpy="1.5707963267948966 0 -1.5707963267948966" xyz="0 0 0.13585"/>
      <geometry>
        <mesh filename="file:///opt/ros/humble/share/ur_description/meshes/ur5/visual/upperarm.dae"/>
      </geometry>
    </visual>
    <collision>
      <origin rpy="1.5707963267948966 0 -1.5707963267948966" xyz="0 0 0.13585"/>
      <geometry>
        <mesh filename="file:///opt/ros/humble/share/ur_description/meshes/ur5/collision/upperarm.stl"/>
      </geometry>
    </collision>
    <inertial>
      <mass value="8.393"/>
      <origin rpy="0 1.5707963267948966 0" xyz="-0.2125 0.0 0.136"/>
      <inertia ixx="0.1338857818623325" ixy="0.0" ixz="0.0" iyy="0.1338857818623325" iyz="0.0" izz="0.0151074"/>
    </inertial>
  </link>
  <link name="left_forearm_link">
    <visual>
      <origin rpy="1.5707963267948966 0 -1.5707963267948966" xyz="0 0 0.0165"/>
      <geometry>
        <mesh filename="file:///opt/ros/humble/share/ur_description/meshes/ur5/visual/forearm.dae"/>
      </geometry>
    </visual>
    <collision>
      <origin rpy="1.5707963267948966 0 -1.5707963267948966" xyz="0 0 0.0165"/>
      <geometry>
        <mesh filename="file:///opt/ros/humble/share/ur_description/meshes/ur5/collision/forearm.stl"/>
      </geometry>
    </collision>
    <inertial>
      <mass value="2.33"/>
      <origin rpy="0 1.5707963267948966 0" xyz="-0.196125 0.0 0.0165"/>
      <inertia ixx="0.03197148268015181" ixy="0.0" ixz="0.0" iyy="0.03197148268015181" iyz="0.0" izz="0.004194"/>
    </inertial>
  </link>
  <link name="left_wrist_1_link">
    <visual>
      <origin rpy="1.5707963267948966 0 0" xyz="0 0 -0.093"/>
      <geometry>
        <mesh filename="file:///opt/ros/humble/share/ur_description/meshes/ur5/visual/wrist1.dae"/>
      </geometry>
    </visual>
    <collision>
      <origin rpy="1.5707963267948966 0 0" xyz="0 0 -0.093"/>
      <geometry>
        <mesh filename="file:///opt/ros/humble/share/ur_description/meshes/ur5/collision/wrist1.stl"/>
      </geometry>
    </collision>
    <inertial>
      <mass value="1.219"/>
      <origin rpy="0 0 0" xyz="0 0 0"/>
      <inertia ixx="0.0020138887777775" ixy="0.0" ixz="0.0" iyy="0.0020138887777775" iyz="0.0" izz="0.0021942"/>
    </inertial>
  </link>
  <link name="left_wrist_2_link">
    <visual>
      <origin rpy="0 0 0" xyz="0 0 -0.095"/>
      <geometry>
        <mesh filename="file:///opt/ros/humble/share/ur_description/meshes/ur5/visual/wrist2.dae"/>
      </geometry>
    </visual>
    <collision>
      <origin rpy="0 0 0" xyz="0 0 -0.095"/>
      <geometry>
        <mesh filename="file:///opt/ros/humble/share/ur_description/meshes/ur5/collision/wrist2.stl"/>
      </geometry>
    </collision>
    <inertial>
      <mass value="1.219"/>
      <origin rpy="0 0 0" xyz="0 0 0"/>
      <inertia ixx="0.0018310388509175" ixy="0.0" ixz="0.0" iyy="0.0018310388509175" iyz="0.0" izz="0.0021942"/>
    </inertial>
  </link>
  <link name="left_wrist_3_link">
    <visual>
      <origin rpy="1.5707963267948966 0 0" xyz="0 0 -0.0818"/>
      <geometry>
        <mesh filename="file:///opt/ros/humble/share/ur_description/meshes/ur5/visual/wrist3.dae"/>
      </geometry>
    </visual>
    <collision>
      <origin rpy="1.5707963267948966 0 0" xyz="0 0 -0.0818"/>
      <geometry>
        <mesh filename="file:///opt/ros/humble/share/ur_description/meshes/ur5/collision/wrist3.stl"/>
      </geometry>
    </collision>
    <inertial>
      <mass value="0.1879"/>
      <origin rpy="0 0 0" xyz="0.0 0.0 -0.01525"/>
      <inertia ixx="8.062472608343e-05" ixy="0.0" ixz="0.0" iyy="8.062472608343e-05" iyz="0.0" izz="0.0001321171875"/>
    </inertial>
  </link>
  <!-- base_joint fixes base_link to the environment -->
  <joint name="left_base_joint" type="fixed">
    <origin rpy="-1.571 -0.785 -2.3568" xyz="0.19894 0 0.545"/>
    <parent link="dual_base"/>
    <child link="left_base_link"/>
  </joint>
  <!-- joints - main serial chain -->
  <joint name="left_base_link-base_link_inertia" type="fixed">
    <parent link="left_base_link"/>
    <child link="left_base_link_inertia"/>
    <!-- 'base_link' is REP-103 aligned (so X+ forward), while the internal
           frames of the robot/controller have X+ pointing backwards.
           Use the joint between 'base_link' and 'base_link_inertia' (a dummy
           link/frame) to introduce the necessary rotation over Z (of pi rad).
      -->
    <origin rpy="0 0 3.141592653589793" xyz="0 0 0"/>
  </joint>
  <joint name="left_shoulder_pan_joint" type="revolute">
    <parent link="left_base_link_inertia"/>
    <child link="left_shoulder_link"/>
    <origin rpy="0 0 -2.365035510390814e-05" xyz="0 0 0.08926466668442085"/>
    <axis xyz="0 0 1"/>
    <limit effort="150.0" lower="-6.283185307179586" upper="6.283185307179586" velocity="3.141592653589793"/>
    <dynamics damping="0" friction="0"/>
  </joint>
  <joint name="left_shoulder_lift_joint" type="revolute">
    <parent link="left_shoulder_link"/>
    <child link="left_upper_arm_link"/>
    <origin rpy="1.571184149968246 0 0.0002916360940085032" xyz="8.806385206328312e-05 0 0"/>
    <axis xyz="0 0 1"/>
    <limit effort="150.0" lower="-6.283185307179586" upper="6.283185307179586" velocity="3.141592653589793"/>
    <dynamics damping="0" friction="0"/>
  </joint>
  <joint name="left_elbow_joint" type="revolute">
    <parent link="left_upper_arm_link"/>
    <child link="left_forearm_link"/>
    <origin rpy="0.0002482960146736955 0.001536264027904251 1.440400441869384e-05" xyz="-0.4252878842215647 0 0"/>
    <axis xyz="0 0 1"/>
    <limit effort="150.0" lower="-3.141592653589793" upper="3.141592653589793" velocity="3.141592653589793"/>
    <dynamics damping="0" friction="0"/>
  </joint>
  <joint name="left_wrist_1_joint" type="revolute">
    <parent link="left_forearm_link"/>
    <child link="left_wrist_1_link"/>
    <origin rpy="0.01275192046165372 0.001382249617172468 -0.0001937671660117227" xyz="-0.3917914392867149 -0.00141411591728907 0.1108883379737456"/>
    <axis xyz="0 0 1"/>
    <limit effort="28.0" lower="-6.283185307179586" upper="6.283185307179586" velocity="3.141592653589793"/>
    <dynamics damping="0" friction="0"/>
  </joint>
  <joint name="left_wrist_2_joint" type="revolute">
    <parent link="left_wrist_1_link"/>
    <child link="left_wrist_2_link"/>
    <origin rpy="1.570132591788392 0 -0.0002022259704481128" xyz="1.367641353687877e-05 -0.09487406529188343 6.297124759081893e-05"/>
    <axis xyz="0 0 1"/>
    <limit effort="28.0" lower="-6.283185307179586" upper="6.283185307179586" velocity="3.141592653589793"/>
    <dynamics damping="0" friction="0"/>
  </joint>
  <joint name="left_wrist_3_joint" type="revolute">
    <parent link="left_wrist_2_link"/>
    <child link="left_wrist_3_link"/>
    <origin rpy="1.571644468346362 3.141592653589793 3.141554326318027" xyz="6.91673446742486e-05 0.08243801219914351 6.991912033163115e-05"/>
    <axis xyz="0 0 1"/>
    <limit effort="28.0" lower="-6.283185307179586" upper="6.283185307179586" velocity="3.141592653589793"/>
    <dynamics damping="0" friction="0"/>
  </joint>
  <link name="left_ft_frame"/>
  <joint name="left_wrist_3_link-ft_frame" type="fixed">
    <parent link="left_wrist_3_link"/>
    <child link="left_ft_frame"/>
    <origin rpy="3.141592653589793 0 0" xyz="0 0 0"/>
  </joint>
  <!-- ROS-Industrial 'base' frame - base_link to UR 'Base' Coordinates transform -->
  <link name="left_base"/>
  <joint name="left_base_link-base_fixed_joint" type="fixed">
    <!-- Note the rotation over Z of pi radians - as base_link is REP-103
           aligned (i.e., has X+ forward, Y+ left and Z+ up), this is needed
           to correctly align 'base' with the 'Base' coordinate system of
           the UR controller.
      -->
    <origin rpy="0 0 3.141592653589793" xyz="0 0 0"/>
    <parent link="left_base_link"/>
    <child link="left_base"/>
  </joint>
  <!-- ROS-Industrial 'flange' frame - attachment point for EEF models -->
  <link name="left_flange"/>
  <joint name="left_wrist_3-flange" type="fixed">
    <parent link="left_wrist_3_link"/>
    <child link="left_flange"/>
    <origin rpy="0 -1.5707963267948966 -1.5707963267948966" xyz="0 0 0"/>
  </joint>
  <!-- ROS-Industrial 'tool0' frame - all-zeros tool frame -->
  <link name="left_tool0"/>
  <joint name="left_flange-tool0" type="fixed">
    <!-- default toolframe - X+ left, Y+ up, Z+ front -->
    <origin rpy="1.5707963267948966 0 1.5707963267948966" xyz="0 0 0"/>
    <parent link="left_flange"/>
    <child link="left_tool0"/>
  </joint>
  <!-- mount the fts to the robot -->
  <joint name="left_ft300_fix" type="fixed">
    <origin rpy="0 0 0" xyz="0 0 -0.004"/>
    <parent link="left_wrist_3_link"/>
    <child link="left_ft300_mounting_plate"/>
  </joint>
  <!-- Link representing the FT300 force-torque sensor -->
  <link name="left_ft300_sensor">
    <inertial>
      <origin rpy="0 0 0" xyz="0 0 -0.017"/>
      <mass value="0.300"/>
      <inertia ixx="0.000262" ixy="0" ixz="1e-06" iyx="0" iyy="0.000265" iyz="1e-06" izx="-1e-06" izy="1e-06" izz="0.000219"/>
    </inertial>
    <visual>
      <origin rpy="0 0 0" xyz="0 0 0"/>
      <geometry>
        <mesh filename="file:///home/jjmczd/dual_v10/install/robotiq_ft_sensor_description/share/robotiq_ft_sensor_description/meshes/visual/robotiq_ft300.STL"/>
      </geometry>
      <material name="Robotiq-Black">
        <color rgba="0.2 0.2 0.2 1.0"/>
      </material>
    </visual>
    <collision>
      <origin rpy="0 0 0" xyz="0 0 0"/>
      <geometry>
        <mesh filename="file:///home/jjmczd/dual_v10/install/robotiq_ft_sensor_description/share/robotiq_ft_sensor_description/meshes/collision/robotiq_ft300.STL"/>
      </geometry>
    </collision>
  </link>
  <!-- Link representing the FT300 mounting plate -->
  <link name="left_ft300_mounting_plate">
    <visual>
      <origin rpy="0 0 0" xyz="0 0 0"/>
      <geometry>
        <mesh filename="file:///home/jjmczd/dual_v10/install/robotiq_ft_sensor_description/share/robotiq_ft_sensor_description/meshes/visual/mountings/robotiq_ft300-G-062-COUPLING_G-50-4M6-1D6_20181119.STL"/>
      </geometry>
      <material name="Robotiq-Grey">
        <color rgba="0.4 0.4 0.4 1.0"/>
      </material>
    </visual>
    <collision>
      <origin rpy="0 0 0" xyz="0 0 0"/>
      <geometry>
        <mesh filename="file:///home/jjmczd/dual_v10/install/robotiq_ft_sensor_description/share/robotiq_ft_sensor_description/meshes/collision/mountings/robotiq_ft300-G-062-COUPLING_G-50-4M6-1D6_20181119.STL"/>
      </geometry>
    </collision>
  </link>
  <!-- Connect force sensor with mounting/coupling plate -->
  <joint name="left_ft300_mounting_plate" type="fixed">
    <origin rpy="0 3.141592653589793 0" xyz="0 0 0.0415"/>
    <parent link="left_ft300_mounting_plate"/>
    <child link="left_ft300_sensor"/>
  </joint>
  <!-- FORCE REFERENCE FRAME _______________________________________________________________________________
            As specified in the documentation
            - The Z axis passes through the center of the depression with positive direction in the tool direction.
            - The X axis traces a symmetric line centered on the connector; the positive direction
                points the opposite way away from the connector.
            - The Y axis uses the right hand thumb rule according to X-Z. -->
  <joint name="left_measurment_joint" type="fixed">
    <origin rpy="0 3.141592653589793 -1.5707963267948966" xyz="0 0 0"/>
    <parent link="left_ft300_sensor"/>
    <child link="left_robotiq_ft_frame_id"/>
  </joint>
  <link name="left_robotiq_ft_frame_id"/>
  <gazebo reference="left_ft300_sensor">
    <material>Gazebo/DarkGrey</material>
  </gazebo>
  <gazebo reference="left_ft300_mounting_plate">
    <material>Gazebo/Gray</material>
  </gazebo>
  <!-- FORCE REFERENCE FRAME _______________________________________________________________________________
    As specified in the documentation
    
    - The Z axis passes through the center of the depression with positive direction in the tool direction.
    - The X axis traces a symmetric line centered on the connector; the positive direction
        points the opposite way away from the connector.
    - The Y axis uses the right hand thumb rule according to X-Z. -->
  <ros2_control name="left_urgripper" type="system">
    <!-- Plugins -->
    <hardware>
      <!-- Set use_dummy to true to connect to a dummy driver for testing purposes. -->
      <param name="use_dummy">false</param>
      <plugin>gazebo_ros2_control/GazeboSystem</plugin>
    </hardware>
    <!-- Joint interfaces -->
    <!-- With Ignition or Hardware, they handle mimic joints, so we only need this command interface activated -->
    <joint name="left_robotiq_85_left_knuckle_joint">
      <command_interface name="position"/>
      <state_interface name="position">
        <param name="initial_value">0.0</param>
      </state_interface>
      <state_interface name="velocity"/>
    </joint>
    <joint name="left_robotiq_85_right_knuckle_joint">
      <param name="mimic">left_robotiq_85_left_knuckle_joint</param>
      <param name="multiplier">-1</param>
      <command_interface name="position"/>
      <state_interface name="position"/>
      <state_interface name="velocity"/>
    </joint>
    <joint name="left_robotiq_85_left_inner_knuckle_joint">
      <param name="mimic">left_robotiq_85_left_knuckle_joint</param>
      <param name="multiplier">1</param>
      <command_interface name="position"/>
      <state_interface name="position"/>
      <state_interface name="velocity"/>
    </joint>
    <joint name="left_robotiq_85_right_inner_knuckle_joint">
      <param name="mimic">left_robotiq_85_left_knuckle_joint</param>
      <param name="multiplier">-1</param>
      <command_interface name="position"/>
      <state_interface name="position"/>
      <state_interface name="velocity"/>
    </joint>
    <joint name="left_robotiq_85_left_finger_tip_joint">
      <param name="mimic">left_robotiq_85_left_knuckle_joint</param>
      <param name="multiplier">-1</param>
      <command_interface name="position"/>
      <state_interface name="position"/>
      <state_interface name="velocity"/>
    </joint>
    <joint name="left_robotiq_85_right_finger_tip_joint">
      <param name="mimic">left_robotiq_85_left_knuckle_joint</param>
      <param name="multiplier">1</param>
      <command_interface name="position"/>
      <state_interface name="position"/>
      <state_interface name="velocity"/>
    </joint>
  </ros2_control>
  <link name="left_robotiq_85_base_link">
    <visual>
      <geometry>
        <mesh filename="file:///home/jjmczd/dual_v10/install/robotiq_description/share/robotiq_description/meshes/visual/2f_85/robotiq_base.dae"/>
      </geometry>
    </visual>
    <collision>
      <geometry>
        <mesh filename="file:///home/jjmczd/dual_v10/install/robotiq_description/share/robotiq_description/meshes/collision/2f_85/robotiq_base.stl"/>
      </geometry>
    </collision>
    <inertial>
      <origin rpy="0 0 0" xyz="0.0 2.274e-05 0.03232288"/>
      <mass value="6.6320197e-01"/>
      <inertia ixx="5.1617816e-04" ixy="2.936e-8" ixz="0.0" iyy="5.8802208e-04" iyz="-3.2296e-7" izz="3.9462776e-04"/>
    </inertial>
  </link>
  <link name="left_robotiq_85_left_knuckle_link">
    <visual>
      <geometry>
        <mesh filename="file:///home/jjmczd/dual_v10/install/robotiq_description/share/robotiq_description/meshes/visual/2f_85/left_knuckle.dae"/>
      </geometry>
    </visual>
    <collision>
      <geometry>
        <mesh filename="file:///home/jjmczd/dual_v10/install/robotiq_description/share/robotiq_description/meshes/collision/2f_85/left_knuckle.stl"/>
      </geometry>
    </collision>
    <inertial>
      <origin rpy="0 0 0" xyz="0.01213197 0.0002 -0.00058647"/>
      <mass value="1.384773208e-02"/>
      <inertia ixx="3.5232e-7" ixy="0.0" ixz="1.1744e-7" iyy="2.31944e-6" iyz="0" izz="2.23136e-6"/>
    </inertial>
  </link>
  <link name="left_robotiq_85_right_knuckle_link">
    <visual>
      <geometry>
        <mesh filename="file:///home/jjmczd/dual_v10/install/robotiq_description/share/robotiq_description/meshes/visual/2f_85/right_knuckle.dae"/>
      </geometry>
    </visual>
    <collision>
      <geometry>
        <mesh filename="file:///home/jjmczd/dual_v10/install/robotiq_description/share/robotiq_description/meshes/collision/2f_85/right_knuckle.stl"/>
      </geometry>
    </collision>
    <inertial>
      <origin rpy="0 0 0" xyz="-0.01213197 0.0002 -0.00058647"/>
      <mass value="1.384773208e-02"/>
      <inertia ixx="3.5232e-7" ixy="0.0" ixz="-1.1744e-7" iyy="2.31944e-6" iyz="0.0" izz="2.23136e-6"/>
    </inertial>
  </link>
  <link name="left_robotiq_85_left_finger_link">
    <visual>
      <geometry>
        <mesh filename="file:///home/jjmczd/dual_v10/install/robotiq_description/share/robotiq_description/meshes/visual/2f_85/left_finger.dae"/>
      </geometry>
    </visual>
    <collision>
      <geometry>
        <mesh filename="file:///home/jjmczd/dual_v10/install/robotiq_description/share/robotiq_description/meshes/collision/2f_85/left_finger.stl"/>
      </geometry>
    </collision>
    <inertial>
      <origin rpy="0 0 0" xyz="0.00346899 -0.00079447 0.01867121"/>
      <mass value="4.260376752e-02"/>
      <inertia ixx="1.385792000000000e-05" ixy="0.0" ixz="-2.17264e-06" iyy="1.183208e-05" iyz="0.0" izz="5.19672e-06"/>
    </inertial>
  </link>
  <link name="left_robotiq_85_right_finger_link">
    <visual>
      <geometry>
        <mesh filename="file:///home/jjmczd/dual_v10/install/robotiq_description/share/robotiq_description/meshes/visual/2f_85/right_finger.dae"/>
      </geometry>
    </visual>
    <collision>
      <geometry>
        <mesh filename="file:///home/jjmczd/dual_v10/install/robotiq_description/share/robotiq_description/meshes/collision/2f_85/right_finger.stl"/>
      </geometry>
    </collision>
    <inertial>
      <origin rpy="0 0 0" xyz="-0.00346899 -5.53e-06 0.01867121"/>
      <mass value="4.260376752000000e-02"/>
      <inertia ixx="1.385792e-05" ixy="0.0" ixz="2.17264e-06" iyy="1.183208e-05" iyz="0.0" izz="5.19672e-06"/>
    </inertial>
  </link>
  <link name="left_robotiq_85_left_inner_knuckle_link">
    <visual>
      <geometry>
        <mesh filename="file:///home/jjmczd/dual_v10/install/robotiq_description/share/robotiq_description/meshes/visual/2f_85/left_inner_knuckle.dae"/>
      </geometry>
    </visual>
    <collision>
      <geometry>
        <mesh filename="file:///home/jjmczd/dual_v10/install/robotiq_description/share/robotiq_description/meshes/collision/2f_85/left_inner_knuckle.stl"/>
      </geometry>
    </collision>
    <inertial>
      <origin rpy="0 0 0" xyz="0.01897699 0.00015001 0.02247101"/>
      <mass value="2.969376448e-02"/>
      <inertia ixx="9.57136e-06" ixy="0.0" ixz="-3.93424e-06" iyy="8.69056e-06" iyz="0.0" izz="8.19144e-06"/>
    </inertial>
  </link>
  <link name="left_robotiq_85_right_inner_knuckle_link">
    <visual>
      <geometry>
        <mesh filename="file:///home/jjmczd/dual_v10/install/robotiq_description/share/robotiq_description/meshes/visual/2f_85/right_inner_knuckle.dae"/>
      </geometry>
    </visual>
    <collision>
      <geometry>
        <mesh filename="file:///home/jjmczd/dual_v10/install/robotiq_description/share/robotiq_description/meshes/collision/2f_85/right_inner_knuckle.stl"/>
      </geometry>
    </collision>
    <inertial>
      <origin rpy="0 0 0" xyz="-0.01926824 5.001e-05 0.02222178"/>
      <mass value="2.969376448e-02"/>
      <inertia ixx="9.42456e-06" ixy="0.0" ixz="3.9636e-06" iyy="8.69056e-06" iyz="0.0" izz="8.33824e-06"/>
    </inertial>
  </link>
  <link name="left_robotiq_85_left_finger_tip_link">
    <visual>
      <geometry>
        <mesh filename="file:///home/jjmczd/dual_v10/install/robotiq_description/share/robotiq_description/meshes/visual/2f_85/left_finger_tip.dae"/>
      </geometry>
    </visual>
    <collision>
      <geometry>
        <mesh filename="file:///home/jjmczd/dual_v10/install/robotiq_description/share/robotiq_description/meshes/collision/2f_85/left_finger_tip.stl"/>
      </geometry>
      <surface>
        <friction>
          <ode>
            <mu1>100000.0</mu1>
            <mu2>100000.0</mu2>
          </ode>
        </friction>
        <contact>
          <ode>
            <kp>1e+5</kp>
            <kd>1</kd>
            <soft_cfm>0</soft_cfm>
            <soft_erp>0.2</soft_erp>
            <minDepth>0.002</minDepth>
            <maxVel>0</maxVel>
          </ode>
        </contact>
      </surface>
    </collision>
    <inertial>
      <origin rpy="0 0 0" xyz="-0.01456706 -0.0008 0.01649701"/>
      <mass value="4.268588744e-02"/>
      <inertia ixx="1.048152e-05" ixy="0.0" ixz="3.5232e-6" iyy="1.197888e-05" iyz="0.0" izz="4.22784e-06"/>
    </inertial>
  </link>
  <link name="left_robotiq_85_right_finger_tip_link">
    <visual>
      <geometry>
        <mesh filename="file:///home/jjmczd/dual_v10/install/robotiq_description/share/robotiq_description/meshes/visual/2f_85/right_finger_tip.dae"/>
      </geometry>
    </visual>
    <collision>
      <geometry>
        <mesh filename="file:///home/jjmczd/dual_v10/install/robotiq_description/share/robotiq_description/meshes/collision/2f_85/right_finger_tip.stl"/>
      </geometry>
      <surface>
        <friction>
          <ode>
            <mu1>100000.0</mu1>
            <mu2>100000.0</mu2>
          </ode>
        </friction>
        <contact>
          <ode>
            <kp>1e+5</kp>
            <kd>1</kd>
            <soft_cfm>0</soft_cfm>
            <soft_erp>0.2</soft_erp>
            <minDepth>0.002</minDepth>
            <maxVel>0</maxVel>
          </ode>
        </contact>
      </surface>
    </collision>
    <inertial>
      <origin rpy="0 0 0" xyz="0.01456706 5e-05 0.01649701"/>
      <mass value="4.268588744e-02"/>
      <inertia ixx="1.048152e-05" ixy="0.0" ixz="-3.5232e-06" iyy="1.197888e-05" iyz="0.0" izz="4.22784e-06"/>
    </inertial>
  </link>
  <joint name="left_robotiq_85_base_joint" type="fixed">
    <parent link="left_robotiq_ft_frame_id"/>
    <child link="left_robotiq_85_base_link"/>
    <origin rpy="0 0 1.5708" xyz="0 0 0"/>
  </joint>
  <joint name="left_robotiq_85_left_knuckle_joint" type="revolute">
    <parent link="left_robotiq_85_base_link"/>
    <child link="left_robotiq_85_left_knuckle_link"/>
    <axis xyz="0 -1 0"/>
    <origin rpy="0 0 0" xyz="0.03060114 0.0 0.05490452"/>
    <limit effort="50" lower="0.0" upper="0.8" velocity="0.5"/>
  </joint>
  <joint name="left_robotiq_85_right_knuckle_joint" type="revolute">
    <parent link="left_robotiq_85_base_link"/>
    <child link="left_robotiq_85_right_knuckle_link"/>
    <axis xyz="0 -1 0"/>
    <origin rpy="0 0 0" xyz="-0.03060114 0.0 0.05490452"/>
    <limit effort="50" lower="-0.8" upper="0.0" velocity="0.5"/>
    <mimic joint="left_robotiq_85_left_knuckle_joint" multiplier="-1"/>
  </joint>
  <joint name="left_robotiq_85_left_finger_joint" type="fixed">
    <parent link="left_robotiq_85_left_knuckle_link"/>
    <child link="left_robotiq_85_left_finger_link"/>
    <origin rpy="0 0 0" xyz="0.03152616 0.0 -0.00376347"/>
  </joint>
  <joint name="left_robotiq_85_right_finger_joint" type="fixed">
    <parent link="left_robotiq_85_right_knuckle_link"/>
    <child link="left_robotiq_85_right_finger_link"/>
    <origin rpy="0 0 0" xyz="-0.03152616 0.0 -0.00376347"/>
  </joint>
  <joint name="left_robotiq_85_left_inner_knuckle_joint" type="continuous">
    <parent link="left_robotiq_85_base_link"/>
    <child link="left_robotiq_85_left_inner_knuckle_link"/>
    <axis xyz="0 -1 0"/>
    <origin rpy="0 0 0" xyz="0.0127 0.0 0.06142"/>
    <mimic joint="left_robotiq_85_left_knuckle_joint"/>
  </joint>
  <joint name="left_robotiq_85_right_inner_knuckle_joint" type="continuous">
    <parent link="left_robotiq_85_base_link"/>
    <child link="left_robotiq_85_right_inner_knuckle_link"/>
    <axis xyz="0 -1 0"/>
    <origin rpy="0 0 0" xyz="-0.0127 0.0 0.06142"/>
    <mimic joint="left_robotiq_85_left_knuckle_joint" multiplier="-1"/>
  </joint>
  <joint name="left_robotiq_85_left_finger_tip_joint" type="continuous">
    <parent link="left_robotiq_85_left_finger_link"/>
    <child link="left_robotiq_85_left_finger_tip_link"/>
    <axis xyz="0 -1 0"/>
    <origin rpy="0 0 0" xyz="0.00563134 0.0 0.04718515"/>
    <mimic joint="left_robotiq_85_left_knuckle_joint" multiplier="-1"/>
  </joint>
  <joint name="left_robotiq_85_right_finger_tip_joint" type="continuous">
    <parent link="left_robotiq_85_right_finger_link"/>
    <child link="left_robotiq_85_right_finger_tip_link"/>
    <axis xyz="0 -1 0"/>
    <origin rpy="0 0 0" xyz="-0.00563134 0.0 0.04718515"/>
    <mimic joint="left_robotiq_85_left_knuckle_joint"/>
  </joint>
  <!-- fix "_mimic" joint interface name suffix causes Moveit2 "Joint not found" Error -->
  <!-- github.com/ros-controls/gazebo_ros2_control/issues/173 -->
  <link name="left_dummy_child1"/>
  <link name="left_dummy_child2"/>
  <link name="left_dummy_child3"/>
  <link name="left_dummy_child4"/>
  <link name="left_dummy_child5"/>
  <joint name="left_robotiq_85_right_knuckle_joint_mimic" type="fixed">
    <parent link="left_robotiq_85_base_link"/>
    <child link="left_dummy_child1"/>
  </joint>
  <joint name="left_robotiq_85_left_inner_knuckle_joint_mimic" type="fixed">
    <parent link="left_robotiq_85_base_link"/>
    <child link="left_dummy_child2"/>
  </joint>
  <joint name="left_robotiq_85_right_inner_knuckle_joint_mimic" type="fixed">
    <parent link="left_robotiq_85_base_link"/>
    <child link="left_dummy_child3"/>
  </joint>
  <joint name="left_robotiq_85_left_finger_tip_joint_mimic" type="fixed">
    <parent link="left_robotiq_85_base_link"/>
    <child link="left_dummy_child4"/>
  </joint>
  <joint name="left_robotiq_85_right_finger_tip_joint_mimic" type="fixed">
    <parent link="left_robotiq_85_base_link"/>
    <child link="left_dummy_child5"/>
  </joint>
  <!-- grasp point for planning -->
  <link name="left_grasp_point"/>
  <joint name="left_grasp_point_joint" type="fixed">
    <parent link="left_tool0"/>
    <child link="left_grasp_point"/>
    <origin rpy="0 0 0" xyz="0 0 0.17"/>
  </joint>
  <gazebo reference="left_robotiq_85_base_joint">
    <disableFixedJointLumping>true</disableFixedJointLumping>
    <provideFeedback>true</provideFeedback>
  </gazebo>
  <gazebo>
    <plugin filename="libgazebo_ros_ft_sensor.so" name="left_gazebo_ros_ft_sensor">
      <ros>
        <namespace>/left_robotiq_ft300</namespace>
      </ros>
      <joint_name>left_robotiq_85_base_joint</joint_name>
      <update_rate>50</update_rate>
      <gaussian_noise>0.01</gaussian_noise>
    </plugin>
  </gazebo>
  <!--
    Base UR robot series xacro macro.

    NOTE this is NOT a URDF. It cannot directly be loaded by consumers
    expecting a flattened '.urdf' file. See the top-level '.xacro' for that
    (but note that .xacro must still be processed by the xacro command).

    This file models the base kinematic chain of a UR robot, which then gets
    parameterised by various configuration files to convert it into a UR3(e),
    UR5(e), UR10(e) or UR16e.

    NOTE the default kinematic parameters (i.e., link lengths, frame locations,
    offsets, etc) do not correspond to any particular robot. They are defaults
    only. There WILL be non-zero offsets between the Forward Kinematics results
    in TF (i.e., robot_state_publisher) and the values reported by the Teach
    Pendant.

    For accurate (and robot-specific) transforms, the 'kinematics_parameters_file'
    parameter MUST point to a .yaml file containing the appropriate values for
    the targeted robot.

    If using the UniversalRobots/Universal_Robots_ROS_Driver, follow the steps
    described in the readme of that repository to extract the kinematic
    calibration from the controller and generate the required .yaml file.

    Main author of the migration to yaml configs Ludovic Delval.

    Contributors to previous versions (in no particular order)

     - Denis Stogl
     - Lovro Ivanov
     - Felix Messmer
     - Kelsey Hawkins
     - Wim Meeussen
     - Shaun Edwards
     - Nadia Hammoudeh Garcia
     - Dave Hershberger
     - G. vd. Hoorn
     - Philip Long
     - Dave Coleman
     - Miguel Prada
     - Mathias Luedtke
     - Marcel Schnirring
     - Felix von Drigalski
     - Felix Exner
     - Jimmy Da Silva
     - Ajit Krisshna N L
     - Muhammad Asif Rana
  -->
  <!--
    NOTE the macro defined in this file is NOT part of the public API of this
          package. Users CANNOT rely on this file being available, or stored in
          this location. Nor can they rely on the existence of the macro.
  -->
  <ros2_control name="right_ur" type="system">
    <hardware>
      <plugin>gazebo_ros2_control/GazeboSystem</plugin>
    </hardware>
    <joint name="right_shoulder_pan_joint">
      <command_interface name="position"/>
      <command_interface name="velocity"/>
      <state_interface name="position">
        <!-- initial position for the FakeSystem and simulation -->
        <param name="initial_value">0.268083</param>
      </state_interface>
      <state_interface name="velocity"/>
      <state_interface name="effort"/>
    </joint>
    <joint name="right_shoulder_lift_joint">
      <command_interface name="position"/>
      <command_interface name="velocity"/>
      <state_interface name="position">
        <!-- initial position for the FakeSystem and simulation -->
        <param name="initial_value">-1.50692</param>
      </state_interface>
      <state_interface name="velocity"/>
      <state_interface name="effort"/>
    </joint>
    <joint name="right_elbow_joint">
      <command_interface name="position"/>
      <command_interface name="velocity"/>
      <state_interface name="position">
        <!-- initial position for the FakeSystem and simulation -->
        <param name="initial_value">-2.18829</param>
      </state_interface>
      <state_interface name="velocity"/>
      <state_interface name="effort"/>
    </joint>
    <joint name="right_wrist_1_joint">
      <command_interface name="position"/>
      <command_interface name="velocity"/>
      <state_interface name="position">
        <!-- initial position for the FakeSystem and simulation -->
        <param name="initial_value">4.33069</param>
      </state_interface>
      <state_interface name="velocity"/>
      <state_interface name="effort"/>
    </joint>
    <joint name="right_wrist_2_joint">
      <command_interface name="position"/>
      <command_interface name="velocity"/>
      <state_interface name="position">
        <!-- initial position for the FakeSystem and simulation -->
        <param name="initial_value">-1.47899</param>
      </state_interface>
      <state_interface name="velocity"/>
      <state_interface name="effort"/>
    </joint>
    <joint name="right_wrist_3_joint">
      <command_interface name="position"/>
      <command_interface name="velocity"/>
      <state_interface name="position">
        <!-- initial position for the FakeSystem and simulation -->
        <param name="initial_value">-1.29364</param>
      </state_interface>
      <state_interface name="velocity"/>
      <state_interface name="effort"/>
    </joint>
  </ros2_control>
  <!-- Add URDF transmission elements (for ros_control) -->
  <!-- NOTE  delete colon （maohao）-->
  <!-- Placeholder for ros2_control transmission which don't yet exist -->
  <!-- links -  main serial chain -->
  <link name="right_base_link"/>
  <link name="right_base_link_inertia">
    <visual>
      <origin rpy="0 0 3.141592653589793" xyz="0 0 0"/>
      <geometry>
        <mesh filename="file:///opt/ros/humble/share/ur_description/meshes/ur5/visual/base.dae"/>
      </geometry>
    </visual>
    <collision>
      <origin rpy="0 0 3.141592653589793" xyz="0 0 0"/>
      <geometry>
        <mesh filename="file:///opt/ros/humble/share/ur_description/meshes/ur5/collision/base.stl"/>
      </geometry>
    </collision>
    <inertial>
      <mass value="4.0"/>
      <origin rpy="0 0 0" xyz="0 0 0"/>
      <inertia ixx="0.00443333156" ixy="0.0" ixz="0.0" iyy="0.00443333156" iyz="0.0" izz="0.0072"/>
    </inertial>
  </link>
  <link name="right_shoulder_link">
    <visual>
      <origin rpy="0 0 3.141592653589793" xyz="0 0 0"/>
      <geometry>
        <mesh filename="file:///opt/ros/humble/share/ur_description/meshes/ur5/visual/shoulder.dae"/>
      </geometry>
    </visual>
    <collision>
      <origin rpy="0 0 3.141592653589793" xyz="0 0 0"/>
      <geometry>
        <mesh filename="file:///opt/ros/humble/share/ur_description/meshes/ur5/collision/shoulder.stl"/>
      </geometry>
    </collision>
    <inertial>
      <mass value="3.7"/>
      <origin rpy="0 0 0" xyz="0 0 0"/>
      <inertia ixx="0.014972352344389999" ixy="0.0" ixz="0.0" iyy="0.014972352344389999" iyz="0.0" izz="0.01040625"/>
    </inertial>
  </link>
  <link name="right_upper_arm_link">
    <visual>
      <origin rpy="1.5707963267948966 0 -1.5707963267948966" xyz="0 0 0.13585"/>
      <geometry>
        <mesh filename="file:///opt/ros/humble/share/ur_description/meshes/ur5/visual/upperarm.dae"/>
      </geometry>
    </visual>
    <collision>
      <origin rpy="1.5707963267948966 0 -1.5707963267948966" xyz="0 0 0.13585"/>
      <geometry>
        <mesh filename="file:///opt/ros/humble/share/ur_description/meshes/ur5/collision/upperarm.stl"/>
      </geometry>
    </collision>
    <inertial>
      <mass value="8.393"/>
      <origin rpy="0 1.5707963267948966 0" xyz="-0.2125 0.0 0.136"/>
      <inertia ixx="0.1338857818623325" ixy="0.0" ixz="0.0" iyy="0.1338857818623325" iyz="0.0" izz="0.0151074"/>
    </inertial>
  </link>
  <link name="right_forearm_link">
    <visual>
      <origin rpy="1.5707963267948966 0 -1.5707963267948966" xyz="0 0 0.0165"/>
      <geometry>
        <mesh filename="file:///opt/ros/humble/share/ur_description/meshes/ur5/visual/forearm.dae"/>
      </geometry>
    </visual>
    <collision>
      <origin rpy="1.5707963267948966 0 -1.5707963267948966" xyz="0 0 0.0165"/>
      <geometry>
        <mesh filename="file:///opt/ros/humble/share/ur_description/meshes/ur5/collision/forearm.stl"/>
      </geometry>
    </collision>
    <inertial>
      <mass value="2.33"/>
      <origin rpy="0 1.5707963267948966 0" xyz="-0.196125 0.0 0.0165"/>
      <inertia ixx="0.03197148268015181" ixy="0.0" ixz="0.0" iyy="0.03197148268015181" iyz="0.0" izz="0.004194"/>
    </inertial>
  </link>
  <link name="right_wrist_1_link">
    <visual>
      <origin rpy="1.5707963267948966 0 0" xyz="0 0 -0.093"/>
      <geometry>
        <mesh filename="file:///opt/ros/humble/share/ur_description/meshes/ur5/visual/wrist1.dae"/>
      </geometry>
    </visual>
    <collision>
      <origin rpy="1.5707963267948966 0 0" xyz="0 0 -0.093"/>
      <geometry>
        <mesh filename="file:///opt/ros/humble/share/ur_description/meshes/ur5/collision/wrist1.stl"/>
      </geometry>
    </collision>
    <inertial>
      <mass value="1.219"/>
      <origin rpy="0 0 0" xyz="0 0 0"/>
      <inertia ixx="0.0020138887777775" ixy="0.0" ixz="0.0" iyy="0.0020138887777775" iyz="0.0" izz="0.0021942"/>
    </inertial>
  </link>
  <link name="right_wrist_2_link">
    <visual>
      <origin rpy="0 0 0" xyz="0 0 -0.095"/>
      <geometry>
        <mesh filename="file:///opt/ros/humble/share/ur_description/meshes/ur5/visual/wrist2.dae"/>
      </geometry>
    </visual>
    <collision>
      <origin rpy="0 0 0" xyz="0 0 -0.095"/>
      <geometry>
        <mesh filename="file:///opt/ros/humble/share/ur_description/meshes/ur5/collision/wrist2.stl"/>
      </geometry>
    </collision>
    <inertial>
      <mass value="1.219"/>
      <origin rpy="0 0 0" xyz="0 0 0"/>
      <inertia ixx="0.0018310388509175" ixy="0.0" ixz="0.0" iyy="0.0018310388509175" iyz="0.0" izz="0.0021942"/>
    </inertial>
  </link>
  <link name="right_wrist_3_link">
    <visual>
      <origin rpy="1.5707963267948966 0 0" xyz="0 0 -0.0818"/>
      <geometry>
        <mesh filename="file:///opt/ros/humble/share/ur_description/meshes/ur5/visual/wrist3.dae"/>
      </geometry>
    </visual>
    <collision>
      <origin rpy="1.5707963267948966 0 0" xyz="0 0 -0.0818"/>
      <geometry>
        <mesh filename="file:///opt/ros/humble/share/ur_description/meshes/ur5/collision/wrist3.stl"/>
      </geometry>
    </collision>
    <inertial>
      <mass value="0.1879"/>
      <origin rpy="0 0 0" xyz="0.0 0.0 -0.01525"/>
      <inertia ixx="8.062472608343e-05" ixy="0.0" ixz="0.0" iyy="8.062472608343e-05" iyz="0.0" izz="0.0001321171875"/>
    </inertial>
  </link>
  <!-- base_joint fixes base_link to the environment -->
  <joint name="right_base_joint" type="fixed">
    <origin rpy="-1.5711 -0.7851 2.3568" xyz="-0.19894 0 0.545"/>
    <parent link="dual_base"/>
    <child link="right_base_link"/>
  </joint>
  <!-- joints - main serial chain -->
  <joint name="right_base_link-base_link_inertia" type="fixed">
    <parent link="right_base_link"/>
    <child link="right_base_link_inertia"/>
    <!-- 'base_link' is REP-103 aligned (so X+ forward), while the internal
           frames of the robot/controller have X+ pointing backwards.
           Use the joint between 'base_link' and 'base_link_inertia' (a dummy
           link/frame) to introduce the necessary rotation over Z (of pi rad).
      -->
    <origin rpy="0 0 3.141592653589793" xyz="0 0 0"/>
  </joint>
  <joint name="right_shoulder_pan_joint" type="revolute">
    <parent link="right_base_link_inertia"/>
    <child link="right_shoulder_link"/>
    <origin rpy="0 0 3.112136468659977e-05" xyz="0 0 0.08930550619588437"/>
    <axis xyz="0 0 1"/>
    <limit effort="150.0" lower="-6.283185307179586" upper="6.283185307179586" velocity="3.141592653589793"/>
    <dynamics damping="0" friction="0"/>
  </joint>
  <joint name="right_shoulder_lift_joint" type="revolute">
    <parent link="right_shoulder_link"/>
    <child link="right_upper_arm_link"/>
    <origin rpy="1.570765449429461 0 2.998489017501842e-05" xyz="5.383932384024152e-05 0 0"/>
    <axis xyz="0 0 1"/>
    <limit effort="150.0" lower="-6.283185307179586" upper="6.283185307179586" velocity="3.141592653589793"/>
    <dynamics damping="0" friction="0"/>
  </joint>
  <joint name="right_elbow_joint" type="revolute">
    <parent link="right_upper_arm_link"/>
    <child link="right_forearm_link"/>
    <origin rpy="3.140813490125675 3.14060040247862 3.141495763052788" xyz="-0.4252929957387768 0 0"/>
    <axis xyz="0 0 1"/>
    <limit effort="150.0" lower="-3.141592653589793" upper="3.141592653589793" velocity="3.141592653589793"/>
    <dynamics damping="0" friction="0"/>
  </joint>
  <joint name="right_wrist_1_joint" type="revolute">
    <parent link="right_forearm_link"/>
    <child link="right_wrist_1_link"/>
    <origin rpy="0.01379475200411217 0.001215208822417934 -8.576961977572128e-05" xyz="-0.3919493366632913 -0.001524368538735334 0.110496502128078"/>
    <axis xyz="0 0 1"/>
    <limit effort="28.0" lower="-6.283185307179586" upper="6.283185307179586" velocity="3.141592653589793"/>
    <dynamics damping="0" friction="0"/>
  </joint>
  <joint name="right_wrist_2_joint" type="revolute">
    <parent link="right_wrist_1_link"/>
    <child link="right_wrist_2_link"/>
    <origin rpy="1.569904493202995 0 -5.118073542250984e-05" xyz="-0.0001081924017169428 -0.09491613880354406 8.464942344109041e-05"/>
    <axis xyz="0 0 1"/>
    <limit effort="28.0" lower="-6.283185307179586" upper="6.283185307179586" velocity="3.141592653589793"/>
    <dynamics damping="0" friction="0"/>
  </joint>
  <joint name="right_wrist_3_joint" type="revolute">
    <parent link="right_wrist_2_link"/>
    <child link="right_wrist_3_link"/>
    <origin rpy="1.57129070983571 3.141592653589793 3.141477716651704" xyz="9.191460226669821e-05 0.0825931865306024 4.083267403420024e-05"/>
    <axis xyz="0 0 1"/>
    <limit effort="28.0" lower="-6.283185307179586" upper="6.283185307179586" velocity="3.141592653589793"/>
    <dynamics damping="0" friction="0"/>
  </joint>
  <link name="right_ft_frame"/>
  <joint name="right_wrist_3_link-ft_frame" type="fixed">
    <parent link="right_wrist_3_link"/>
    <child link="right_ft_frame"/>
    <origin rpy="3.141592653589793 0 0" xyz="0 0 0"/>
  </joint>
  <!-- ROS-Industrial 'base' frame - base_link to UR 'Base' Coordinates transform -->
  <link name="right_base"/>
  <joint name="right_base_link-base_fixed_joint" type="fixed">
    <!-- Note the rotation over Z of pi radians - as base_link is REP-103
           aligned (i.e., has X+ forward, Y+ left and Z+ up), this is needed
           to correctly align 'base' with the 'Base' coordinate system of
           the UR controller.
      -->
    <origin rpy="0 0 3.141592653589793" xyz="0 0 0"/>
    <parent link="right_base_link"/>
    <child link="right_base"/>
  </joint>
  <!-- ROS-Industrial 'flange' frame - attachment point for EEF models -->
  <link name="right_flange"/>
  <joint name="right_wrist_3-flange" type="fixed">
    <parent link="right_wrist_3_link"/>
    <child link="right_flange"/>
    <origin rpy="0 -1.5707963267948966 -1.5707963267948966" xyz="0 0 0"/>
  </joint>
  <!-- ROS-Industrial 'tool0' frame - all-zeros tool frame -->
  <link name="right_tool0"/>
  <joint name="right_flange-tool0" type="fixed">
    <!-- default toolframe - X+ left, Y+ up, Z+ front -->
    <origin rpy="1.5707963267948966 0 1.5707963267948966" xyz="0 0 0"/>
    <parent link="right_flange"/>
    <child link="right_tool0"/>
  </joint>
  <!-- mount the fts to the robot -->
  <joint name="right_ft300_fix" type="fixed">
    <origin rpy="0 0 0" xyz="0 0 -0.004"/>
    <parent link="right_wrist_3_link"/>
    <child link="right_ft300_mounting_plate"/>
  </joint>
  <!-- Link representing the FT300 force-torque sensor -->
  <link name="right_ft300_sensor">
    <inertial>
      <origin rpy="0 0 0" xyz="0 0 -0.017"/>
      <mass value="0.300"/>
      <inertia ixx="0.000262" ixy="0" ixz="1e-06" iyx="0" iyy="0.000265" iyz="1e-06" izx="-1e-06" izy="1e-06" izz="0.000219"/>
    </inertial>
    <visual>
      <origin rpy="0 0 0" xyz="0 0 0"/>
      <geometry>
        <mesh filename="file:///home/jjmczd/dual_v10/install/robotiq_ft_sensor_description/share/robotiq_ft_sensor_description/meshes/visual/robotiq_ft300.STL"/>
      </geometry>
      <material name="Robotiq-Black">
        <color rgba="0.2 0.2 0.2 1.0"/>
      </material>
    </visual>
    <collision>
      <origin rpy="0 0 0" xyz="0 0 0"/>
      <geometry>
        <mesh filename="file:///home/jjmczd/dual_v10/install/robotiq_ft_sensor_description/share/robotiq_ft_sensor_description/meshes/collision/robotiq_ft300.STL"/>
      </geometry>
    </collision>
  </link>
  <!-- Link representing the FT300 mounting plate -->
  <link name="right_ft300_mounting_plate">
    <visual>
      <origin rpy="0 0 0" xyz="0 0 0"/>
      <geometry>
        <mesh filename="file:///home/jjmczd/dual_v10/install/robotiq_ft_sensor_description/share/robotiq_ft_sensor_description/meshes/visual/mountings/robotiq_ft300-G-062-COUPLING_G-50-4M6-1D6_20181119.STL"/>
      </geometry>
      <material name="Robotiq-Grey">
        <color rgba="0.4 0.4 0.4 1.0"/>
      </material>
    </visual>
    <collision>
      <origin rpy="0 0 0" xyz="0 0 0"/>
      <geometry>
        <mesh filename="file:///home/jjmczd/dual_v10/install/robotiq_ft_sensor_description/share/robotiq_ft_sensor_description/meshes/collision/mountings/robotiq_ft300-G-062-COUPLING_G-50-4M6-1D6_20181119.STL"/>
      </geometry>
    </collision>
  </link>
  <!-- Connect force sensor with mounting/coupling plate -->
  <joint name="right_ft300_mounting_plate" type="fixed">
    <origin rpy="0 3.141592653589793 0" xyz="0 0 0.0415"/>
    <parent link="right_ft300_mounting_plate"/>
    <child link="right_ft300_sensor"/>
  </joint>
  <!-- FORCE REFERENCE FRAME _______________________________________________________________________________
            As specified in the documentation
            - The Z axis passes through the center of the depression with positive direction in the tool direction.
            - The X axis traces a symmetric line centered on the connector; the positive direction
                points the opposite way away from the connector.
            - The Y axis uses the right hand thumb rule according to X-Z. -->
  <joint name="right_measurment_joint" type="fixed">
    <origin rpy="0 3.141592653589793 -1.5707963267948966" xyz="0 0 0"/>
    <parent link="right_ft300_sensor"/>
    <child link="right_robotiq_ft_frame_id"/>
  </joint>
  <link name="right_robotiq_ft_frame_id"/>
  <gazebo reference="right_ft300_sensor">
    <material>Gazebo/DarkGrey</material>
  </gazebo>
  <gazebo reference="right_ft300_mounting_plate">
    <material>Gazebo/Gray</material>
  </gazebo>
  <!-- FORCE REFERENCE FRAME _______________________________________________________________________________
    As specified in the documentation
    
    - The Z axis passes through the center of the depression with positive direction in the tool direction.
    - The X axis traces a symmetric line centered on the connector; the positive direction
        points the opposite way away from the connector.
    - The Y axis uses the right hand thumb rule according to X-Z. -->
  <ros2_control name="right_urgripper" type="system">
    <!-- Plugins -->
    <hardware>
      <!-- Set use_dummy to true to connect to a dummy driver for testing purposes. -->
      <param name="use_dummy">false</param>
      <plugin>gazebo_ros2_control/GazeboSystem</plugin>
    </hardware>
    <!-- Joint interfaces -->
    <!-- With Ignition or Hardware, they handle mimic joints, so we only need this command interface activated -->
    <joint name="right_robotiq_85_left_knuckle_joint">
      <command_interface name="position"/>
      <state_interface name="position">
        <param name="initial_value">0.0</param>
      </state_interface>
      <state_interface name="velocity"/>
    </joint>
    <joint name="right_robotiq_85_right_knuckle_joint">
      <param name="mimic">right_robotiq_85_left_knuckle_joint</param>
      <param name="multiplier">-1</param>
      <command_interface name="position"/>
      <state_interface name="position"/>
      <state_interface name="velocity"/>
    </joint>
    <joint name="right_robotiq_85_left_inner_knuckle_joint">
      <param name="mimic">right_robotiq_85_left_knuckle_joint</param>
      <param name="multiplier">1</param>
      <command_interface name="position"/>
      <state_interface name="position"/>
      <state_interface name="velocity"/>
    </joint>
    <joint name="right_robotiq_85_right_inner_knuckle_joint">
      <param name="mimic">right_robotiq_85_left_knuckle_joint</param>
      <param name="multiplier">-1</param>
      <command_interface name="position"/>
      <state_interface name="position"/>
      <state_interface name="velocity"/>
    </joint>
    <joint name="right_robotiq_85_left_finger_tip_joint">
      <param name="mimic">right_robotiq_85_left_knuckle_joint</param>
      <param name="multiplier">-1</param>
      <command_interface name="position"/>
      <state_interface name="position"/>
      <state_interface name="velocity"/>
    </joint>
    <joint name="right_robotiq_85_right_finger_tip_joint">
      <param name="mimic">right_robotiq_85_left_knuckle_joint</param>
      <param name="multiplier">1</param>
      <command_interface name="position"/>
      <state_interface name="position"/>
      <state_interface name="velocity"/>
    </joint>
  </ros2_control>
  <link name="right_robotiq_85_base_link">
    <visual>
      <geometry>
        <mesh filename="file:///home/jjmczd/dual_v10/install/robotiq_description/share/robotiq_description/meshes/visual/2f_85/robotiq_base.dae"/>
      </geometry>
    </visual>
    <collision>
      <geometry>
        <mesh filename="file:///home/jjmczd/dual_v10/install/robotiq_description/share/robotiq_description/meshes/collision/2f_85/robotiq_base.stl"/>
      </geometry>
    </collision>
    <inertial>
      <origin rpy="0 0 0" xyz="0.0 2.274e-05 0.03232288"/>
      <mass value="6.6320197e-01"/>
      <inertia ixx="5.1617816e-04" ixy="2.936e-8" ixz="0.0" iyy="5.8802208e-04" iyz="-3.2296e-7" izz="3.9462776e-04"/>
    </inertial>
  </link>
  <link name="right_robotiq_85_left_knuckle_link">
    <visual>
      <geometry>
        <mesh filename="file:///home/jjmczd/dual_v10/install/robotiq_description/share/robotiq_description/meshes/visual/2f_85/left_knuckle.dae"/>
      </geometry>
    </visual>
    <collision>
      <geometry>
        <mesh filename="file:///home/jjmczd/dual_v10/install/robotiq_description/share/robotiq_description/meshes/collision/2f_85/left_knuckle.stl"/>
      </geometry>
    </collision>
    <inertial>
      <origin rpy="0 0 0" xyz="0.01213197 0.0002 -0.00058647"/>
      <mass value="1.384773208e-02"/>
      <inertia ixx="3.5232e-7" ixy="0.0" ixz="1.1744e-7" iyy="2.31944e-6" iyz="0" izz="2.23136e-6"/>
    </inertial>
  </link>
  <link name="right_robotiq_85_right_knuckle_link">
    <visual>
      <geometry>
        <mesh filename="file:///home/jjmczd/dual_v10/install/robotiq_description/share/robotiq_description/meshes/visual/2f_85/right_knuckle.dae"/>
      </geometry>
    </visual>
    <collision>
      <geometry>
        <mesh filename="file:///home/jjmczd/dual_v10/install/robotiq_description/share/robotiq_description/meshes/collision/2f_85/right_knuckle.stl"/>
      </geometry>
    </collision>
    <inertial>
      <origin rpy="0 0 0" xyz="-0.01213197 0.0002 -0.00058647"/>
      <mass value="1.384773208e-02"/>
      <inertia ixx="3.5232e-7" ixy="0.0" ixz="-1.1744e-7" iyy="2.31944e-6" iyz="0.0" izz="2.23136e-6"/>
    </inertial>
  </link>
  <link name="right_robotiq_85_left_finger_link">
    <visual>
      <geometry>
        <mesh filename="file:///home/jjmczd/dual_v10/install/robotiq_description/share/robotiq_description/meshes/visual/2f_85/left_finger.dae"/>
      </geometry>
    </visual>
    <collision>
      <geometry>
        <mesh filename="file:///home/jjmczd/dual_v10/install/robotiq_description/share/robotiq_description/meshes/collision/2f_85/left_finger.stl"/>
      </geometry>
    </collision>
    <inertial>
      <origin rpy="0 0 0" xyz="0.00346899 -0.00079447 0.01867121"/>
      <mass value="4.260376752e-02"/>
      <inertia ixx="1.385792000000000e-05" ixy="0.0" ixz="-2.17264e-06" iyy="1.183208e-05" iyz="0.0" izz="5.19672e-06"/>
    </inertial>
  </link>
  <link name="right_robotiq_85_right_finger_link">
    <visual>
      <geometry>
        <mesh filename="file:///home/jjmczd/dual_v10/install/robotiq_description/share/robotiq_description/meshes/visual/2f_85/right_finger.dae"/>
      </geometry>
    </visual>
    <collision>
      <geometry>
        <mesh filename="file:///home/jjmczd/dual_v10/install/robotiq_description/share/robotiq_description/meshes/collision/2f_85/right_finger.stl"/>
      </geometry>
    </collision>
    <inertial>
      <origin rpy="0 0 0" xyz="-0.00346899 -5.53e-06 0.01867121"/>
      <mass value="4.260376752000000e-02"/>
      <inertia ixx="1.385792e-05" ixy="0.0" ixz="2.17264e-06" iyy="1.183208e-05" iyz="0.0" izz="5.19672e-06"/>
    </inertial>
  </link>
  <link name="right_robotiq_85_left_inner_knuckle_link">
    <visual>
      <geometry>
        <mesh filename="file:///home/jjmczd/dual_v10/install/robotiq_description/share/robotiq_description/meshes/visual/2f_85/left_inner_knuckle.dae"/>
      </geometry>
    </visual>
    <collision>
      <geometry>
        <mesh filename="file:///home/jjmczd/dual_v10/install/robotiq_description/share/robotiq_description/meshes/collision/2f_85/left_inner_knuckle.stl"/>
      </geometry>
    </collision>
    <inertial>
      <origin rpy="0 0 0" xyz="0.01897699 0.00015001 0.02247101"/>
      <mass value="2.969376448e-02"/>
      <inertia ixx="9.57136e-06" ixy="0.0" ixz="-3.93424e-06" iyy="8.69056e-06" iyz="0.0" izz="8.19144e-06"/>
    </inertial>
  </link>
  <link name="right_robotiq_85_right_inner_knuckle_link">
    <visual>
      <geometry>
        <mesh filename="file:///home/jjmczd/dual_v10/install/robotiq_description/share/robotiq_description/meshes/visual/2f_85/right_inner_knuckle.dae"/>
      </geometry>
    </visual>
    <collision>
      <geometry>
        <mesh filename="file:///home/jjmczd/dual_v10/install/robotiq_description/share/robotiq_description/meshes/collision/2f_85/right_inner_knuckle.stl"/>
      </geometry>
    </collision>
    <inertial>
      <origin rpy="0 0 0" xyz="-0.01926824 5.001e-05 0.02222178"/>
      <mass value="2.969376448e-02"/>
      <inertia ixx="9.42456e-06" ixy="0.0" ixz="3.9636e-06" iyy="8.69056e-06" iyz="0.0" izz="8.33824e-06"/>
    </inertial>
  </link>
  <link name="right_robotiq_85_left_finger_tip_link">
    <visual>
      <geometry>
        <mesh filename="file:///home/jjmczd/dual_v10/install/robotiq_description/share/robotiq_description/meshes/visual/2f_85/left_finger_tip.dae"/>
      </geometry>
    </visual>
    <collision>
      <geometry>
        <mesh filename="file:///home/jjmczd/dual_v10/install/robotiq_description/share/robotiq_description/meshes/collision/2f_85/left_finger_tip.stl"/>
      </geometry>
      <surface>
        <friction>
          <ode>
            <mu1>100000.0</mu1>
            <mu2>100000.0</mu2>
          </ode>
        </friction>
        <contact>
          <ode>
            <kp>1e+5</kp>
            <kd>1</kd>
            <soft_cfm>0</soft_cfm>
            <soft_erp>0.2</soft_erp>
            <minDepth>0.002</minDepth>
            <maxVel>0</maxVel>
          </ode>
        </contact>
      </surface>
    </collision>
    <inertial>
      <origin rpy="0 0 0" xyz="-0.01456706 -0.0008 0.01649701"/>
      <mass value="4.268588744e-02"/>
      <inertia ixx="1.048152e-05" ixy="0.0" ixz="3.5232e-6" iyy="1.197888e-05" iyz="0.0" izz="4.22784e-06"/>
    </inertial>
  </link>
  <link name="right_robotiq_85_right_finger_tip_link">
    <visual>
      <geometry>
        <mesh filename="file:///home/jjmczd/dual_v10/install/robotiq_description/share/robotiq_description/meshes/visual/2f_85/right_finger_tip.dae"/>
      </geometry>
    </visual>
    <collision>
      <geometry>
        <mesh filename="file:///home/jjmczd/dual_v10/install/robotiq_description/share/robotiq_description/meshes/collision/2f_85/right_finger_tip.stl"/>
      </geometry>
      <surface>
        <friction>
          <ode>
            <mu1>100000.0</mu1>
            <mu2>100000.0</mu2>
          </ode>
        </friction>
        <contact>
          <ode>
            <kp>1e+5</kp>
            <kd>1</kd>
            <soft_cfm>0</soft_cfm>
            <soft_erp>0.2</soft_erp>
            <minDepth>0.002</minDepth>
            <maxVel>0</maxVel>
          </ode>
        </contact>
      </surface>
    </collision>
    <inertial>
      <origin rpy="0 0 0" xyz="0.01456706 5e-05 0.01649701"/>
      <mass value="4.268588744e-02"/>
      <inertia ixx="1.048152e-05" ixy="0.0" ixz="-3.5232e-06" iyy="1.197888e-05" iyz="0.0" izz="4.22784e-06"/>
    </inertial>
  </link>
  <joint name="right_robotiq_85_base_joint" type="fixed">
    <parent link="right_robotiq_ft_frame_id"/>
    <child link="right_robotiq_85_base_link"/>
    <origin rpy="0 0 1.5708" xyz="0 0 0"/>
  </joint>
  <joint name="right_robotiq_85_left_knuckle_joint" type="revolute">
    <parent link="right_robotiq_85_base_link"/>
    <child link="right_robotiq_85_left_knuckle_link"/>
    <axis xyz="0 -1 0"/>
    <origin rpy="0 0 0" xyz="0.03060114 0.0 0.05490452"/>
    <limit effort="50" lower="0.0" upper="0.8" velocity="0.5"/>
  </joint>
  <joint name="right_robotiq_85_right_knuckle_joint" type="revolute">
    <parent link="right_robotiq_85_base_link"/>
    <child link="right_robotiq_85_right_knuckle_link"/>
    <axis xyz="0 -1 0"/>
    <origin rpy="0 0 0" xyz="-0.03060114 0.0 0.05490452"/>
    <limit effort="50" lower="-0.8" upper="0.0" velocity="0.5"/>
    <mimic joint="right_robotiq_85_left_knuckle_joint" multiplier="-1"/>
  </joint>
  <joint name="right_robotiq_85_left_finger_joint" type="fixed">
    <parent link="right_robotiq_85_left_knuckle_link"/>
    <child link="right_robotiq_85_left_finger_link"/>
    <origin rpy="0 0 0" xyz="0.03152616 0.0 -0.00376347"/>
  </joint>
  <joint name="right_robotiq_85_right_finger_joint" type="fixed">
    <parent link="right_robotiq_85_right_knuckle_link"/>
    <child link="right_robotiq_85_right_finger_link"/>
    <origin rpy="0 0 0" xyz="-0.03152616 0.0 -0.00376347"/>
  </joint>
  <joint name="right_robotiq_85_left_inner_knuckle_joint" type="continuous">
    <parent link="right_robotiq_85_base_link"/>
    <child link="right_robotiq_85_left_inner_knuckle_link"/>
    <axis xyz="0 -1 0"/>
    <origin rpy="0 0 0" xyz="0.0127 0.0 0.06142"/>
    <mimic joint="right_robotiq_85_left_knuckle_joint"/>
  </joint>
  <joint name="right_robotiq_85_right_inner_knuckle_joint" type="continuous">
    <parent link="right_robotiq_85_base_link"/>
    <child link="right_robotiq_85_right_inner_knuckle_link"/>
    <axis xyz="0 -1 0"/>
    <origin rpy="0 0 0" xyz="-0.0127 0.0 0.06142"/>
    <mimic joint="right_robotiq_85_left_knuckle_joint" multiplier="-1"/>
  </joint>
  <joint name="right_robotiq_85_left_finger_tip_joint" type="continuous">
    <parent link="right_robotiq_85_left_finger_link"/>
    <child link="right_robotiq_85_left_finger_tip_link"/>
    <axis xyz="0 -1 0"/>
    <origin rpy="0 0 0" xyz="0.00563134 0.0 0.04718515"/>
    <mimic joint="right_robotiq_85_left_knuckle_joint" multiplier="-1"/>
  </joint>
  <joint name="right_robotiq_85_right_finger_tip_joint" type="continuous">
    <parent link="right_robotiq_85_right_finger_link"/>
    <child link="right_robotiq_85_right_finger_tip_link"/>
    <axis xyz="0 -1 0"/>
    <origin rpy="0 0 0" xyz="-0.00563134 0.0 0.04718515"/>
    <mimic joint="right_robotiq_85_left_knuckle_joint"/>
  </joint>
  <!-- fix "_mimic" joint interface name suffix causes Moveit2 "Joint not found" Error -->
  <!-- github.com/ros-controls/gazebo_ros2_control/issues/173 -->
  <link name="right_dummy_child1"/>
  <link name="right_dummy_child2"/>
  <link name="right_dummy_child3"/>
  <link name="right_dummy_child4"/>
  <link name="right_dummy_child5"/>
  <joint name="right_robotiq_85_right_knuckle_joint_mimic" type="fixed">
    <parent link="right_robotiq_85_base_link"/>
    <child link="right_dummy_child1"/>
  </joint>
  <joint name="right_robotiq_85_left_inner_knuckle_joint_mimic" type="fixed">
    <parent link="right_robotiq_85_base_link"/>
    <child link="right_dummy_child2"/>
  </joint>
  <joint name="right_robotiq_85_right_inner_knuckle_joint_mimic" type="fixed">
    <parent link="right_robotiq_85_base_link"/>
    <child link="right_dummy_child3"/>
  </joint>
  <joint name="right_robotiq_85_left_finger_tip_joint_mimic" type="fixed">
    <parent link="right_robotiq_85_base_link"/>
    <child link="right_dummy_child4"/>
  </joint>
  <joint name="right_robotiq_85_right_finger_tip_joint_mimic" type="fixed">
    <parent link="right_robotiq_85_base_link"/>
    <child link="right_dummy_child5"/>
  </joint>
  <!-- grasp point for planning -->
  <link name="right_grasp_point"/>
  <joint name="right_grasp_point_joint" type="fixed">
    <parent link="right_tool0"/>
    <child link="right_grasp_point"/>
    <origin rpy="0 0 0" xyz="0 0 0.17"/>
  </joint>
  <gazebo reference="right_robotiq_85_base_joint">
    <disableFixedJointLumping>true</disableFixedJointLumping>
    <provideFeedback>true</provideFeedback>
  </gazebo>
  <gazebo>
    <plugin filename="libgazebo_ros_ft_sensor.so" name="right_gazebo_ros_ft_sensor">
      <ros>
        <namespace>/right_robotiq_ft300</namespace>
      </ros>
      <joint_name>right_robotiq_85_base_joint</joint_name>
      <update_rate>50</update_rate>
      <gaussian_noise>0.01</gaussian_noise>
    </plugin>
  </gazebo>
  <gazebo reference="dual_base">
    <material>Gazebo/Blue</material>
    <gravity>false</gravity>
    <selfCollide>false</selfCollide>
  </gazebo>
  <gazebo>
    <plugin filename="libgazebo_ros2_control.so" name="gazebo_ros2_control">
      <parameters>/home/jjmczd/dual_v10/install/dual_description/share/dual_description/config/controllers.yaml</parameters>
    </plugin>
  </gazebo>
  <gazebo>
    <!-- grasp fix plugin for gazebo classic -->
    <plugin filename="libgazebo_grasp_fix.so" name="gazebo_grasp_fix">
      <arm>
        <arm_name>left_robotiq_85_gripper_arm</arm_name>
        <palm_link>left_wrist_3_link</palm_link>
        <gripper_link>left_robotiq_85_left_finger_tip_link</gripper_link>
        <gripper_link>left_robotiq_85_right_finger_tip_link</gripper_link>
        <gripper_link>left_robotiq_85_left_knuckle_link</gripper_link>
        <gripper_link>left_robotiq_85_right_knuckle_link</gripper_link>
        <gripper_link>left_robotiq_85_left_inner_knuckle_link</gripper_link>
        <gripper_link>left_robotiq_85_right_inner_knuckle_link</gripper_link>
      </arm>
      <arm>
        <arm_name>right_robotiq_85_gripper_arm</arm_name>
        <palm_link>right_wrist_3_link</palm_link>
        <gripper_link>right_robotiq_85_left_finger_tip_link</gripper_link>
        <gripper_link>right_robotiq_85_right_finger_tip_link</gripper_link>
        <gripper_link>right_robotiq_85_left_knuckle_link</gripper_link>
        <gripper_link>right_robotiq_85_right_knuckle_link</gripper_link>
        <gripper_link>right_robotiq_85_left_inner_knuckle_link</gripper_link>
        <gripper_link>right_robotiq_85_right_inner_knuckle_link</gripper_link>
      </arm>
      <forces_angle_tolerance>150</forces_angle_tolerance>
      <update_rate>30</update_rate>
      <grip_count_threshold>1</grip_count_threshold>
      <max_grip_count>2</max_grip_count>
      <release_tolerance>0.01</release_tolerance>
      <disable_collisions_on_attach>false</disable_collisions_on_attach>
      <contact_topic>__default_topic__</contact_topic>
    </plugin>
  </gazebo>
</robot>
