<sdf version='1.7'>
  <world name='default'>
    <gravity>0 0 -9.8</gravity>
    <model name='ground_plane'>
      <static>1</static>
      <link name='link'>
        <collision name='collision'>
          <geometry>
            <plane>
              <normal>0 0 1</normal>
              <size>100 100</size>
            </plane>
          </geometry>
          <surface>
            <friction>
              <ode>
                <mu>100</mu>
                <mu2>50</mu2>
              </ode>
              <torsional>
                <ode/>
              </torsional>
            </friction>
            <contact>
              <ode/>
            </contact>
            <bounce/>
          </surface>
          <max_contacts>10</max_contacts>
        </collision>
        <visual name='visual'>
          <cast_shadows>0</cast_shadows>
          <geometry>
            <plane>
              <normal>0 0 1</normal>
              <size>100 100</size>
            </plane>
          </geometry>
          <material>
            <script>
              <uri>file://media/materials/scripts/gazebo.material</uri>
              <name>Gazebo/Grey</name>
            </script>
          </material>
        </visual>
        <self_collide>0</self_collide>
        <enable_wind>0</enable_wind>
        <kinematic>0</kinematic>
      </link>
    </model>
    <light name='sun' type='directional'>
      <cast_shadows>1</cast_shadows>
      <pose>0 0 10 0 -0 0</pose>
      <diffuse>0.8 0.8 0.8 1</diffuse>
      <specular>0.2 0.2 0.2 1</specular>
      <attenuation>
        <range>1000</range>
        <constant>0.9</constant>
        <linear>0.01</linear>
        <quadratic>0.001</quadratic>
      </attenuation>
      <direction>-0.5 0.1 -0.9</direction>
      <spot>
        <inner_angle>0</inner_angle>
        <outer_angle>0</outer_angle>
        <falloff>0</falloff>
      </spot>
    </light>
    <scene>
      <shadows>0</shadows>
      <ambient>0.4 0.4 0.4 1</ambient>
      <background>0.7 0.7 0.7 1</background>
    </scene>
    <plugin name='gazebo_link_attacher' filename='libgazebo_link_attacher.so'/>
    <magnetic_field>6e-06 2.3e-05 -4.2e-05</magnetic_field>
    <atmosphere type='adiabatic'/>
    <physics type='ode'>
      <max_step_size>0.001</max_step_size>
      <real_time_factor>1</real_time_factor>
      <real_time_update_rate>1000</real_time_update_rate>
    </physics>
    <audio>
      <device>default</device>
    </audio>
    <wind/>
    <spherical_coordinates>
      <surface_model>EARTH_WGS84</surface_model>
      <latitude_deg>0</latitude_deg>
      <longitude_deg>0</longitude_deg>
      <elevation>0</elevation>
      <heading_deg>0</heading_deg>
    </spherical_coordinates>
    <state world_name='default'>
      <sim_time>129 345000000</sim_time>
      <real_time>63 1532241</real_time>
      <wall_time>1729673698 813141273</wall_time>
      <iterations>60563</iterations>
      <model name='dual-ur5-gripper'>
        <pose>0 -1.6e-05 0 -2.9e-05 -0 0</pose>
        <scale>1 1 1</scale>
        <link name='dual_base'>
          <pose>0 -1.6e-05 0 -2.9e-05 -0 0</pose>
          <velocity>0 -0 0 -0 -0 -0</velocity>
          <acceleration>0 -0 0 -1e-06 -0 -0</acceleration>
          <wrench>0 -0 0 0 -0 0</wrench>
        </link>
        <link name='left_forearm_link'>
          <pose>0.676963 -0.036121 0.63449 3.08268 -0.27183 1.00591</pose>
          <velocity>0.001872 0.001478 -0.009125 -0.020414 0.020553 -0.00026</velocity>
          <acceleration>0.422741 0.104385 -3.91967 2.3575 0.819536 -1.37599</acceleration>
          <wrench>0.984987 0.243217 -9.13283 0 -0 0</wrench>
        </link>
        <link name='left_robotiq_85_base_link'>
          <pose>0.406982 -0.445993 0.370218 1.99412 0.788577 0.3531</pose>
          <velocity>0.000681 0.005074 -0.02187 0.214101 -0.000838 0.031312</velocity>
          <acceleration>-3e-06 -1e-06 2e-06 0.0031 -0.087781 -0.019666</acceleration>
          <wrench>-2e-06 -1e-06 1e-06 0 -0 0</wrench>
        </link>
        <link name='left_robotiq_85_left_finger_tip_link'>
          <pose>0.455913 -0.5235 0.293682 1.99428 0.788504 0.353325</pose>
          <velocity>0.003993 0.024383 -0.03903 0.361685 -0.032712 0.15796</velocity>
          <acceleration>3.0937 -0.557676 -3.73947 0.946693 -0.937626 -0.12288</acceleration>
          <wrench>0.132058 -0.023805 -0.159623 0 -0 0</wrench>
        </link>
        <link name='left_robotiq_85_left_inner_knuckle_link'>
          <pose>0.417953 -0.50163 0.343425 1.99422 0.788532 0.353239</pose>
          <velocity>0.002446 0.011152 -0.033774 0.280335 -0.015143 0.08815</velocity>
          <acceleration>1.24543 2.09009 -0.921428 -1.66241 -0.701296 0.837368</acceleration>
          <wrench>0.036982 0.062063 -0.027361 0 -0 0</wrench>
        </link>
        <link name='left_robotiq_85_left_knuckle_link'>
          <pose>0.429519 -0.491037 0.332613 1.99414 0.788569 0.353138</pose>
          <velocity>0.002123 0.01383 -0.031496 0.236735 -0.005726 0.050734</velocity>
          <acceleration>0.187491 0.930877 0.02281 -1.11883 -0.818857 -1.98826</acceleration>
          <wrench>0.010584 0.052549 0.001288 0 -0 0</wrench>
        </link>
        <link name='left_robotiq_85_right_finger_tip_link'>
          <pose>0.366288 -0.556536 0.389807 1.9942 0.788535 0.35321</pose>
          <velocity>0.00774 -0.003376 -0.050532 0.265405 -0.011918 0.075338</velocity>
          <acceleration>4.31758 -1.74566 -5.47705 -1.57691 1.23253 -0.714853</acceleration>
          <wrench>0.1843 -0.074515 -0.233793 0 -0 0</wrench>
        </link>
        <link name='left_robotiq_85_right_inner_knuckle_link'>
          <pose>0.401154 -0.507821 0.361442 1.99428 0.788512 0.353309</pose>
          <velocity>0.002624 0.006768 -0.035111 0.349384 -0.030057 0.147403</velocity>
          <acceleration>2.79928 -2.34791 -3.85701 0.410617 0.282188 2.54902</acceleration>
          <wrench>0.083121 -0.069718 -0.114529 0 -0 0</wrench>
        </link>
        <link name='left_robotiq_85_right_knuckle_link'>
          <pose>0.389042 -0.505954 0.376027 1.99422 0.788524 0.353251</pose>
          <velocity>0.002553 0.003267 -0.034721 0.303507 -0.020148 0.108036</velocity>
          <acceleration>1.02129 -3.02985 -1.95991 0.551308 1.03388 -1.83829</acceleration>
          <wrench>0.057653 -0.17104 -0.11064 0 -0 0</wrench>
        </link>
        <link name='left_shoulder_link'>
          <pose>0.262012 -0.063167 0.544984 1.57106 -0.278983 0.784589</pose>
          <velocity>-0 0 0 -0.020469 0.020499 7e-06</velocity>
          <acceleration>-0 0 0 -1.17564 -1.2191 -3.1334</acceleration>
          <wrench>-0 0 0 0 -0 0</wrench>
        </link>
        <link name='left_upper_arm_link'>
          <pose>0.262072 -0.063106 0.545007 2.95837 0.211993 -3.07666</pose>
          <velocity>1e-06 1e-06 -3e-06 -0.020302 0.020667 -0.000818</velocity>
          <acceleration>-1.74441 -1.93702 -5.64654 1.87004 1.27031 -2.6307</acceleration>
          <wrench>-14.6408 -16.2574 -47.3914 0 -0 0</wrench>
        </link>
        <link name='left_wrist_1_link'>
          <pose>0.495174 -0.332513 0.422585 2.95192 -0.203102 1.597</pose>
          <velocity>-0.002561 -0.002801 0.000662 -0.019217 0.021878 -0.006538</velocity>
          <acceleration>-2.56072 -2.80073 0.662105 2.65679 0.242534 2.91554</acceleration>
          <wrench>-3.12152 -3.41409 0.807107 0 -0 0</wrench>
        </link>
        <link name='left_wrist_2_link'>
          <pose>0.40195 -0.331321 0.405008 -2.1405 1.22001 1.01681</pose>
          <velocity>-0.002938 -0.002529 0.002679 0.213234 0.018986 0.037312</velocity>
          <acceleration>-2.9375 -2.52903 2.67878 1.92009 0.57715 0.339623</acceleration>
          <wrench>-3.58082 -3.08289 3.26544 0 -0 0</wrench>
        </link>
        <link name='left_wrist_3_link'>
          <pose>0.405412 -0.410133 0.381076 1.99412 0.788578 0.353099</pose>
          <velocity>-0.000451 0.002701 -0.014193 0.214091 -0.000608 0.031381</velocity>
          <acceleration>0.383269 4.45043 -19.8505 -2.66014 0.255752 -0.104395</acceleration>
          <wrench>0.186997 2.17137 -9.68507 0 -0 0</wrench>
        </link>
        <link name='right_forearm_link'>
          <pose>-0.57337 -0.352789 0.554046 2.83896 -0.446006 2.98082</pose>
          <velocity>0.005065 -0.005575 -0.004108 0.011994 0.011095 0.001059</velocity>
          <acceleration>3.99281 -4.2111 -6.24854 -2.3088 -0.841685 2.93996</acceleration>
          <wrench>9.30325 -9.81186 -14.5591 0 -0 0</wrench>
        </link>
        <link name='right_robotiq_85_base_link'>
          <pose>-0.177001 -0.446871 0.189271 2.20988 0.080202 0.05248</pose>
          <velocity>-0.004136 0.008189 -0.02102 0.131772 0.028625 -0.040009</velocity>
          <acceleration>2e-06 -0 0 0.000443 0.055093 0.031083</acceleration>
          <wrench>1e-06 -0 0 0 -0 0</wrench>
        </link>
        <link name='right_robotiq_85_left_finger_tip_link'>
          <pose>-0.113663 -0.524832 0.123998 2.20989 0.080108 0.052605</pose>
          <velocity>-0.01282 0.0119 -0.034408 0.146714 -0.064029 0.085171</velocity>
          <acceleration>-1.14091 -4.05041 -2.86536 1.17264 -0.826305 -1.70517</acceleration>
          <wrench>-0.048701 -0.172895 -0.12231 0 -0 0</wrench>
        </link>
        <link name='right_robotiq_85_left_inner_knuckle_link'>
          <pose>-0.164704 -0.495592 0.151736 2.20323 0.127319 -0.011684</pose>
          <velocity>-0.007159 0.012642 -0.027792 0.125083 0.070103 -0.096048</velocity>
          <acceleration>-1.67341 -1.05133 -0.580401 -1.83406 1.24479 0.33121</acceleration>
          <wrench>-0.04969 -0.031218 -0.017234 0 -0 0</wrench>
        </link>
        <link name='right_robotiq_85_left_knuckle_link'>
          <pose>-0.146849 -0.489417 0.154176 2.20323 0.127324 -0.011693</pose>
          <velocity>-0.006842 0.011607 -0.027489 0.12413 0.076011 -0.10403</velocity>
          <acceleration>-1.0804 -1.88211 -1.26804 -0.400904 0.979936 -2.26258</acceleration>
          <wrench>-0.06099 -0.106248 -0.071583 0 -0 0</wrench>
        </link>
        <link name='right_robotiq_85_right_finger_tip_link'>
          <pose>-0.241475 -0.531546 0.134285 2.20987 0.080279 0.052376</pose>
          <velocity>-0.004593 0.015596 -0.032659 0.119441 0.105086 -0.14331</velocity>
          <acceleration>2.37315 -4.04178 -3.27215 -1.23571 1.49045 -1.77814</acceleration>
          <wrench>0.1013 -0.172527 -0.139675 0 -0 0</wrench>
        </link>
        <link name='right_robotiq_85_right_inner_knuckle_link'>
          <pose>-0.189988 -0.49692 0.153771 2.21347 0.032738 0.116184</pose>
          <velocity>-0.007154 0.013386 -0.027243 0.141691 -0.03288 0.043088</velocity>
          <acceleration>2.4379 -1.32882 -1.27279 1.57609 -0.665509 2.11094</acceleration>
          <wrench>0.07239 -0.039458 -0.037794 0 -0 0</wrench>
        </link>
        <link name='right_robotiq_85_right_knuckle_link'>
          <pose>-0.20777 -0.492617 0.159079 2.21347 0.032741 0.11618</pose>
          <velocity>-0.00683 0.013398 -0.026167 0.141157 -0.029573 0.03862</velocity>
          <acceleration>1.29548 -2.17785 -1.7631 0.600741 -0.502602 0.542209</acceleration>
          <wrench>0.073132 -0.122943 -0.09953 0 -0 0</wrench>
        </link>
        <link name='right_shoulder_link'>
          <pose>-0.262064 -0.063173 0.544982 1.57105 0.534079 -0.784874</pose>
          <velocity>0 0 0 0.011527 0.011536 4e-06</velocity>
          <acceleration>0 0 0 0.87737 -0.890491 -3.13756</acceleration>
          <wrench>0 0 0 0 -0 0</wrench>
        </link>
        <link name='right_upper_arm_link'>
          <pose>-0.262031 -0.063204 0.544953 -2.60795 0.021384 0.749214</pose>
          <velocity>-0 0 -1e-06 0.018784 0.00428 0.017359</velocity>
          <acceleration>1.18012 -1.43617 -0.923959 0.553769 1.06722 -2.17865</acceleration>
          <wrench>9.90472 -12.0538 -7.75479 0 -0 0</wrench>
        </link>
        <link name='right_wrist_1_link'>
          <pose>-0.264389 -0.371009 0.289406 2.80433 0.413106 -1.48071</pose>
          <velocity>0.002149 -0.002073 -0.007755 0.013669 0.009494 0.005041</velocity>
          <acceleration>2.14852 -2.07349 -7.75463 -2.23031 -0.252764 1.8945</acceleration>
          <wrench>2.61905 -2.52759 -9.4529 0 -0 0</wrench>
        </link>
        <link name='right_wrist_2_link'>
          <pose>-0.176358 -0.350265 0.260609 -2.04327 -0.839799 -0.976828</pose>
          <velocity>0.001771 -0.001236 -0.008307 0.131832 0.037208 -0.033663</velocity>
          <acceleration>1.77057 -1.23613 -8.30688 3.12076 0.656218 -1.75127</acceleration>
          <wrench>2.15832 -1.50685 -10.1261 0 -0 0</wrench>
        </link>
        <link name='right_wrist_3_link'>
          <pose>-0.176791 -0.416719 0.211566 2.20988 0.080202 0.052479</pose>
          <velocity>-0.002291 0.005243 -0.017052 0.131771 0.028485 -0.040113</velocity>
          <acceleration>-3.65071 7.41452 -19.976 3.09574 -0.305209 1.60542</acceleration>
          <wrench>-1.78118 3.61754 -9.74631 0 -0 0</wrench>
        </link>
      </model>
      <model name='glass'>
        <pose>-0.600205 -0.499935 0.060026 -0.000615 -0.000676 -0.001217</pose>
        <scale>1 1 1</scale>
        <link name='link_4'>
          <pose>-0.600205 -0.499935 0.060026 -0.000615 -0.000676 -0.001217</pose>
          <velocity>0 0 0 0 -0 0</velocity>
          <acceleration>0.069974 -0.065874 -0.044741 1.09744 1.16574 -0</acceleration>
          <wrench>0.069974 -0.065874 -0.044741 0 -0 0</wrench>
        </link>
      </model>
      <model name='ground_plane'>
        <pose>0 0 0 0 -0 0</pose>
        <scale>1 1 1</scale>
        <link name='link'>
          <pose>0 0 0 0 -0 0</pose>
          <velocity>0 0 0 0 -0 0</velocity>
          <acceleration>0 0 0 0 -0 0</acceleration>
          <wrench>0 0 0 0 -0 0</wrench>
        </link>
      </model>
      <model name='small_bottle'>
        <pose>0.200646 -0.500832 0.085214 0.00237 0.001984 -0.001694</pose>
        <scale>1 1 1</scale>
        <link name='link_1'>
          <pose>0.200646 -0.500832 0.085214 0.00237 0.001984 -0.001694</pose>
          <velocity>0 0 0 0 -0 0</velocity>
          <acceleration>0 0 -9.8 0 -0 0</acceleration>
          <wrench>0 0 -9.8 0 -0 0</wrench>
        </link>
      </model>
      <light name='sun'>
        <pose>0 0 10 0 -0 0</pose>
      </light>
    </state>
    <gui fullscreen='0'>
      <camera name='user_camera'>
        <pose>0.231599 -1.47425 0.441791 0 0.159704 2.13949</pose>
        <view_controller>orbit</view_controller>
        <projection_type>perspective</projection_type>
      </camera>
    </gui>
    <model name='dual-ur5-gripper'>
      <joint name='world_dual_base_joint' type='fixed'>
        <pose relative_to='__model__'>0 0 0 0 -0 0</pose>
        <parent>world</parent>
        <child>dual_base</child>
      </joint>
      <link name='dual_base'>
        <pose relative_to='world_dual_base_joint'>0 0 0 0 -0 0</pose>
        <inertial>
          <pose>0 0 0.545 0 -0 0</pose>
          <mass>8</mass>
          <inertia>
            <ixx>0.0116302</ixx>
            <ixy>1.09632e-09</ixy>
            <ixz>1.38394e-07</ixz>
            <iyy>0.328253</iyy>
            <iyz>7.02442e-07</iyz>
            <izz>0.325484</izz>
          </inertia>
        </inertial>
        <collision name='dual_base_collision'>
          <pose>0 0 0 0 -0 0</pose>
          <geometry>
            <mesh>
              <scale>1 1 1</scale>
              <uri>file:///home/jjmczd/dual_v10/install/dual_description/share/dual_description/meshes/dual_base.stl</uri>
            </mesh>
          </geometry>
          <surface>
            <contact>
              <ode/>
            </contact>
            <friction>
              <ode/>
              <torsional>
                <ode/>
              </torsional>
            </friction>
            <bounce/>
          </surface>
          <max_contacts>10</max_contacts>
        </collision>
        <collision name='dual_base_fixed_joint_lump__left_base_link_inertia_collision_1'>
          <pose>0.19894 0 0.545 -1.571 -0.785 -2.3568</pose>
          <geometry>
            <mesh>
              <scale>1 1 1</scale>
              <uri>file:///opt/ros/humble/share/ur_description/meshes/ur5/collision/base.stl</uri>
            </mesh>
          </geometry>
          <max_contacts>10</max_contacts>
          <surface>
            <contact>
              <ode/>
            </contact>
            <bounce/>
            <friction>
              <torsional>
                <ode/>
              </torsional>
              <ode/>
            </friction>
          </surface>
        </collision>
        <collision name='dual_base_fixed_joint_lump__right_base_link_inertia_collision_2'>
          <pose>-0.19894 0 0.545 -1.5711 -0.7851 2.3568</pose>
          <geometry>
            <mesh>
              <scale>1 1 1</scale>
              <uri>file:///opt/ros/humble/share/ur_description/meshes/ur5/collision/base.stl</uri>
            </mesh>
          </geometry>
          <max_contacts>10</max_contacts>
          <surface>
            <contact>
              <ode/>
            </contact>
            <bounce/>
            <friction>
              <torsional>
                <ode/>
              </torsional>
              <ode/>
            </friction>
          </surface>
        </collision>
        <visual name='dual_base_visual'>
          <pose>0 0 0 0 -0 0</pose>
          <geometry>
            <mesh>
              <scale>1 1 1</scale>
              <uri>file:///home/jjmczd/dual_v10/install/dual_description/share/dual_description/meshes/dual_base.stl</uri>
            </mesh>
          </geometry>
          <material>
            <script>
              <name>Gazebo/Blue</name>
              <uri>file://media/materials/scripts/gazebo.material</uri>
            </script>
          </material>
        </visual>
        <visual name='dual_base_fixed_joint_lump__left_base_link_inertia_visual_1'>
          <pose>0.19894 0 0.545 -1.571 -0.785 -2.3568</pose>
          <geometry>
            <mesh>
              <scale>1 1 1</scale>
              <uri>file:///opt/ros/humble/share/ur_description/meshes/ur5/visual/base.dae</uri>
            </mesh>
          </geometry>
        </visual>
        <visual name='dual_base_fixed_joint_lump__right_base_link_inertia_visual_2'>
          <pose>-0.19894 0 0.545 -1.5711 -0.7851 2.3568</pose>
          <geometry>
            <mesh>
              <scale>1 1 1</scale>
              <uri>file:///opt/ros/humble/share/ur_description/meshes/ur5/visual/base.dae</uri>
            </mesh>
          </geometry>
        </visual>
        <self_collide>0</self_collide>
        <gravity>0</gravity>
        <enable_wind>0</enable_wind>
        <kinematic>0</kinematic>
      </link>
      <joint name='left_shoulder_pan_joint' type='revolute'>
        <pose relative_to='dual_base'>0.262012 -0.063167 0.544987 1.571 0.785024 0.784793</pose>
        <parent>dual_base</parent>
        <child>left_shoulder_link</child>
        <axis>
          <xyz>0 0 1</xyz>
          <limit>
            <lower>-6.28319</lower>
            <upper>6.28319</upper>
            <effort>150</effort>
            <velocity>3.14159</velocity>
          </limit>
          <dynamics>
            <damping>0</damping>
            <friction>0</friction>
            <spring_reference>0</spring_reference>
            <spring_stiffness>0</spring_stiffness>
          </dynamics>
        </axis>
      </joint>
      <link name='left_shoulder_link'>
        <pose relative_to='left_shoulder_pan_joint'>0 0 0 0 -0 0</pose>
        <inertial>
          <pose>0 0 0 0 -0 0</pose>
          <mass>3.7</mass>
          <inertia>
            <ixx>0.0149724</ixx>
            <ixy>0</ixy>
            <ixz>0</ixz>
            <iyy>0.0149724</iyy>
            <iyz>0</iyz>
            <izz>0.0104063</izz>
          </inertia>
        </inertial>
        <collision name='left_shoulder_link_collision'>
          <pose>0 0 0 0 -0 3.14159</pose>
          <geometry>
            <mesh>
              <scale>1 1 1</scale>
              <uri>file:///opt/ros/humble/share/ur_description/meshes/ur5/collision/shoulder.stl</uri>
            </mesh>
          </geometry>
          <max_contacts>10</max_contacts>
          <surface>
            <contact>
              <ode/>
            </contact>
            <bounce/>
            <friction>
              <torsional>
                <ode/>
              </torsional>
              <ode/>
            </friction>
          </surface>
        </collision>
        <visual name='left_shoulder_link_visual'>
          <pose>0 0 0 0 -0 3.14159</pose>
          <geometry>
            <mesh>
              <scale>1 1 1</scale>
              <uri>file:///opt/ros/humble/share/ur_description/meshes/ur5/visual/shoulder.dae</uri>
            </mesh>
          </geometry>
        </visual>
        <self_collide>0</self_collide>
        <enable_wind>0</enable_wind>
        <kinematic>0</kinematic>
      </link>
      <joint name='left_shoulder_lift_joint' type='revolute'>
        <pose relative_to='left_shoulder_link'>8.8e-05 0 0 1.57118 -0 0.000292</pose>
        <parent>left_shoulder_link</parent>
        <child>left_upper_arm_link</child>
        <axis>
          <xyz>0 0 1</xyz>
          <limit>
            <lower>-6.28319</lower>
            <upper>6.28319</upper>
            <effort>150</effort>
            <velocity>3.14159</velocity>
          </limit>
          <dynamics>
            <damping>0</damping>
            <friction>0</friction>
            <spring_reference>0</spring_reference>
            <spring_stiffness>0</spring_stiffness>
          </dynamics>
        </axis>
      </joint>
      <link name='left_upper_arm_link'>
        <pose relative_to='left_shoulder_lift_joint'>0 0 0 0 -0 0</pose>
        <inertial>
          <pose>-0.2125 0 0.136 3.14159 1.57079 3.14159</pose>
          <mass>8.393</mass>
          <inertia>
            <ixx>0.133886</ixx>
            <ixy>0</ixy>
            <ixz>0</ixz>
            <iyy>0.133886</iyy>
            <iyz>0</iyz>
            <izz>0.0151074</izz>
          </inertia>
        </inertial>
        <collision name='left_upper_arm_link_collision'>
          <pose>0 0 0.13585 1.5708 0 -1.5708</pose>
          <geometry>
            <mesh>
              <scale>1 1 1</scale>
              <uri>file:///opt/ros/humble/share/ur_description/meshes/ur5/collision/upperarm.stl</uri>
            </mesh>
          </geometry>
          <max_contacts>10</max_contacts>
          <surface>
            <contact>
              <ode/>
            </contact>
            <bounce/>
            <friction>
              <torsional>
                <ode/>
              </torsional>
              <ode/>
            </friction>
          </surface>
        </collision>
        <visual name='left_upper_arm_link_visual'>
          <pose>0 0 0.13585 1.5708 0 -1.5708</pose>
          <geometry>
            <mesh>
              <scale>1 1 1</scale>
              <uri>file:///opt/ros/humble/share/ur_description/meshes/ur5/visual/upperarm.dae</uri>
            </mesh>
          </geometry>
        </visual>
        <self_collide>0</self_collide>
        <enable_wind>0</enable_wind>
        <kinematic>0</kinematic>
      </link>
      <joint name='left_elbow_joint' type='revolute'>
        <pose relative_to='left_upper_arm_link'>-0.425288 0 0 0.000248 0.001536 1.4e-05</pose>
        <parent>left_upper_arm_link</parent>
        <child>left_forearm_link</child>
        <axis>
          <xyz>0 0 1</xyz>
          <limit>
            <lower>-3.14159</lower>
            <upper>3.14159</upper>
            <effort>150</effort>
            <velocity>3.14159</velocity>
          </limit>
          <dynamics>
            <damping>0</damping>
            <friction>0</friction>
            <spring_reference>0</spring_reference>
            <spring_stiffness>0</spring_stiffness>
          </dynamics>
        </axis>
      </joint>
      <link name='left_forearm_link'>
        <pose relative_to='left_elbow_joint'>0 0 0 0 -0 0</pose>
        <inertial>
          <pose>-0.196125 0 0.0165 3.14159 1.57079 3.14159</pose>
          <mass>2.33</mass>
          <inertia>
            <ixx>0.0319715</ixx>
            <ixy>0</ixy>
            <ixz>0</ixz>
            <iyy>0.0319715</iyy>
            <iyz>0</iyz>
            <izz>0.004194</izz>
          </inertia>
        </inertial>
        <collision name='left_forearm_link_collision'>
          <pose>0 0 0.0165 1.5708 0 -1.5708</pose>
          <geometry>
            <mesh>
              <scale>1 1 1</scale>
              <uri>file:///opt/ros/humble/share/ur_description/meshes/ur5/collision/forearm.stl</uri>
            </mesh>
          </geometry>
          <max_contacts>10</max_contacts>
          <surface>
            <contact>
              <ode/>
            </contact>
            <bounce/>
            <friction>
              <torsional>
                <ode/>
              </torsional>
              <ode/>
            </friction>
          </surface>
        </collision>
        <visual name='left_forearm_link_visual'>
          <pose>0 0 0.0165 1.5708 0 -1.5708</pose>
          <geometry>
            <mesh>
              <scale>1 1 1</scale>
              <uri>file:///opt/ros/humble/share/ur_description/meshes/ur5/visual/forearm.dae</uri>
            </mesh>
          </geometry>
        </visual>
        <self_collide>0</self_collide>
        <enable_wind>0</enable_wind>
        <kinematic>0</kinematic>
      </link>
      <joint name='left_wrist_1_joint' type='revolute'>
        <pose relative_to='left_forearm_link'>-0.391791 -0.001414 0.110888 0.012752 0.001382 -0.000194</pose>
        <parent>left_forearm_link</parent>
        <child>left_wrist_1_link</child>
        <axis>
          <xyz>0 0 1</xyz>
          <limit>
            <lower>-6.28319</lower>
            <upper>6.28319</upper>
            <effort>28</effort>
            <velocity>3.14159</velocity>
          </limit>
          <dynamics>
            <damping>0</damping>
            <friction>0</friction>
            <spring_reference>0</spring_reference>
            <spring_stiffness>0</spring_stiffness>
          </dynamics>
        </axis>
      </joint>
      <link name='left_wrist_1_link'>
        <pose relative_to='left_wrist_1_joint'>0 0 0 0 -0 0</pose>
        <inertial>
          <pose>0 0 0 0 -0 0</pose>
          <mass>1.219</mass>
          <inertia>
            <ixx>0.00201389</ixx>
            <ixy>0</ixy>
            <ixz>0</ixz>
            <iyy>0.00201389</iyy>
            <iyz>0</iyz>
            <izz>0.0021942</izz>
          </inertia>
        </inertial>
        <collision name='left_wrist_1_link_collision'>
          <pose>0 0 -0.093 1.5708 -0 0</pose>
          <geometry>
            <mesh>
              <scale>1 1 1</scale>
              <uri>file:///opt/ros/humble/share/ur_description/meshes/ur5/collision/wrist1.stl</uri>
            </mesh>
          </geometry>
          <max_contacts>10</max_contacts>
          <surface>
            <contact>
              <ode/>
            </contact>
            <bounce/>
            <friction>
              <torsional>
                <ode/>
              </torsional>
              <ode/>
            </friction>
          </surface>
        </collision>
        <visual name='left_wrist_1_link_visual'>
          <pose>0 0 -0.093 1.5708 -0 0</pose>
          <geometry>
            <mesh>
              <scale>1 1 1</scale>
              <uri>file:///opt/ros/humble/share/ur_description/meshes/ur5/visual/wrist1.dae</uri>
            </mesh>
          </geometry>
        </visual>
        <self_collide>0</self_collide>
        <enable_wind>0</enable_wind>
        <kinematic>0</kinematic>
      </link>
      <joint name='left_wrist_2_joint' type='revolute'>
        <pose relative_to='left_wrist_1_link'>1.4e-05 -0.094874 6.3e-05 1.57013 -0 -0.000202</pose>
        <parent>left_wrist_1_link</parent>
        <child>left_wrist_2_link</child>
        <axis>
          <xyz>0 0 1</xyz>
          <limit>
            <lower>-6.28319</lower>
            <upper>6.28319</upper>
            <effort>28</effort>
            <velocity>3.14159</velocity>
          </limit>
          <dynamics>
            <damping>0</damping>
            <friction>0</friction>
            <spring_reference>0</spring_reference>
            <spring_stiffness>0</spring_stiffness>
          </dynamics>
        </axis>
      </joint>
      <link name='left_wrist_2_link'>
        <pose relative_to='left_wrist_2_joint'>0 0 0 0 -0 0</pose>
        <inertial>
          <pose>0 0 0 0 -0 0</pose>
          <mass>1.219</mass>
          <inertia>
            <ixx>0.00183104</ixx>
            <ixy>0</ixy>
            <ixz>0</ixz>
            <iyy>0.00183104</iyy>
            <iyz>0</iyz>
            <izz>0.0021942</izz>
          </inertia>
        </inertial>
        <collision name='left_wrist_2_link_collision'>
          <pose>0 0 -0.095 0 -0 0</pose>
          <geometry>
            <mesh>
              <scale>1 1 1</scale>
              <uri>file:///opt/ros/humble/share/ur_description/meshes/ur5/collision/wrist2.stl</uri>
            </mesh>
          </geometry>
          <max_contacts>10</max_contacts>
          <surface>
            <contact>
              <ode/>
            </contact>
            <bounce/>
            <friction>
              <torsional>
                <ode/>
              </torsional>
              <ode/>
            </friction>
          </surface>
        </collision>
        <visual name='left_wrist_2_link_visual'>
          <pose>0 0 -0.095 0 -0 0</pose>
          <geometry>
            <mesh>
              <scale>1 1 1</scale>
              <uri>file:///opt/ros/humble/share/ur_description/meshes/ur5/visual/wrist2.dae</uri>
            </mesh>
          </geometry>
        </visual>
        <self_collide>0</self_collide>
        <enable_wind>0</enable_wind>
        <kinematic>0</kinematic>
      </link>
      <joint name='left_wrist_3_joint' type='revolute'>
        <pose relative_to='left_wrist_2_link'>6.9e-05 0.082438 7e-05 -1.56995 -0 -3.8e-05</pose>
        <parent>left_wrist_2_link</parent>
        <child>left_wrist_3_link</child>
        <axis>
          <xyz>0 0 1</xyz>
          <limit>
            <lower>-6.28319</lower>
            <upper>6.28319</upper>
            <effort>28</effort>
            <velocity>3.14159</velocity>
          </limit>
          <dynamics>
            <damping>0</damping>
            <friction>0</friction>
            <spring_reference>0</spring_reference>
            <spring_stiffness>0</spring_stiffness>
          </dynamics>
        </axis>
      </joint>
      <link name='left_wrist_3_link'>
        <pose relative_to='left_wrist_3_joint'>0 0 0 0 -0 0</pose>
        <inertial>
          <pose>-0 -0 0.027638 0 -0 0</pose>
          <mass>0.4879</mass>
          <inertia>
            <ixx>0.000904714</ixx>
            <ixy>3.67394e-22</ixy>
            <ixz>1e-06</ixz>
            <iyy>0.000907714</iyy>
            <iyz>-1e-06</iyz>
            <izz>0.000351117</izz>
          </inertia>
        </inertial>
        <collision name='left_wrist_3_link_collision'>
          <pose>0 0 -0.0818 1.5708 -0 0</pose>
          <geometry>
            <mesh>
              <scale>1 1 1</scale>
              <uri>file:///opt/ros/humble/share/ur_description/meshes/ur5/collision/wrist3.stl</uri>
            </mesh>
          </geometry>
          <max_contacts>10</max_contacts>
          <surface>
            <contact>
              <ode/>
            </contact>
            <bounce/>
            <friction>
              <torsional>
                <ode/>
              </torsional>
              <ode/>
            </friction>
          </surface>
        </collision>
        <collision name='left_wrist_3_link_fixed_joint_lump__left_ft300_mounting_plate_collision_1'>
          <pose>0 0 -0.004 0 -0 0</pose>
          <geometry>
            <mesh>
              <scale>1 1 1</scale>
              <uri>file:///home/jjmczd/dual_v10/install/robotiq_ft_sensor_description/share/robotiq_ft_sensor_description/meshes/collision/mountings/robotiq_ft300-G-062-COUPLING_G-50-4M6-1D6_20181119.STL</uri>
            </mesh>
          </geometry>
          <surface>
            <contact>
              <ode/>
            </contact>
            <friction>
              <ode/>
              <torsional>
                <ode/>
              </torsional>
            </friction>
            <bounce/>
          </surface>
          <max_contacts>10</max_contacts>
        </collision>
        <collision name='left_wrist_3_link_fixed_joint_lump__left_ft300_sensor_collision_2'>
          <pose>0 0 0.0375 3.14159 -0 3.14159</pose>
          <geometry>
            <mesh>
              <scale>1 1 1</scale>
              <uri>file:///home/jjmczd/dual_v10/install/robotiq_ft_sensor_description/share/robotiq_ft_sensor_description/meshes/collision/robotiq_ft300.STL</uri>
            </mesh>
          </geometry>
          <surface>
            <contact>
              <ode/>
            </contact>
            <friction>
              <ode/>
              <torsional>
                <ode/>
              </torsional>
            </friction>
            <bounce/>
          </surface>
          <max_contacts>10</max_contacts>
        </collision>
        <visual name='left_wrist_3_link_visual'>
          <pose>0 0 -0.0818 1.5708 -0 0</pose>
          <geometry>
            <mesh>
              <scale>1 1 1</scale>
              <uri>file:///opt/ros/humble/share/ur_description/meshes/ur5/visual/wrist3.dae</uri>
            </mesh>
          </geometry>
        </visual>
        <visual name='left_wrist_3_link_fixed_joint_lump__left_ft300_mounting_plate_visual_1'>
          <pose>0 0 -0.004 0 -0 0</pose>
          <geometry>
            <mesh>
              <scale>1 1 1</scale>
              <uri>file:///home/jjmczd/dual_v10/install/robotiq_ft_sensor_description/share/robotiq_ft_sensor_description/meshes/visual/mountings/robotiq_ft300-G-062-COUPLING_G-50-4M6-1D6_20181119.STL</uri>
            </mesh>
          </geometry>
          <material>
            <script>
              <name>Gazebo/Gray</name>
              <uri>file://media/materials/scripts/gazebo.material</uri>
            </script>
          </material>
        </visual>
        <visual name='left_wrist_3_link_fixed_joint_lump__left_ft300_sensor_visual_2'>
          <pose>0 0 0.0375 3.14159 -0 3.14159</pose>
          <geometry>
            <mesh>
              <scale>1 1 1</scale>
              <uri>file:///home/jjmczd/dual_v10/install/robotiq_ft_sensor_description/share/robotiq_ft_sensor_description/meshes/visual/robotiq_ft300.STL</uri>
            </mesh>
          </geometry>
          <material>
            <script>
              <name>Gazebo/DarkGrey</name>
              <uri>file://media/materials/scripts/gazebo.material</uri>
            </script>
          </material>
        </visual>
        <self_collide>0</self_collide>
        <enable_wind>0</enable_wind>
        <kinematic>0</kinematic>
      </link>
      <joint name='left_robotiq_85_base_joint' type='revolute'>
        <pose relative_to='left_wrist_3_link'>0 0 0.0375 0 -0 0</pose>
        <parent>left_wrist_3_link</parent>
        <child>left_robotiq_85_base_link</child>
        <axis>
          <limit>
            <lower>0</lower>
            <upper>0</upper>
          </limit>
          <dynamics>
            <damping>0</damping>
            <friction>0</friction>
            <spring_reference>0</spring_reference>
            <spring_stiffness>0</spring_stiffness>
          </dynamics>
          <xyz>0 0 1</xyz>
        </axis>
        <physics>
          <provide_feedback>1</provide_feedback>
          <ode>
            <limit>
              <cfm>0</cfm>
              <erp>0.2</erp>
            </limit>
            <provide_feedback>1</provide_feedback>
          </ode>
        </physics>
      </joint>
      <link name='left_robotiq_85_base_link'>
        <pose relative_to='left_robotiq_85_base_joint'>0 0 0 0 -0 0</pose>
        <inertial>
          <pose>0 2.3e-05 0.032323 0 -0 0</pose>
          <mass>0.663202</mass>
          <inertia>
            <ixx>0.000516178</ixx>
            <ixy>2.936e-08</ixy>
            <ixz>0</ixz>
            <iyy>0.000588022</iyy>
            <iyz>-3.2296e-07</iyz>
            <izz>0.000394628</izz>
          </inertia>
        </inertial>
        <collision name='left_robotiq_85_base_link_collision'>
          <pose>0 0 0 0 -0 0</pose>
          <geometry>
            <mesh>
              <scale>1 1 1</scale>
              <uri>file:///home/jjmczd/dual_v10/install/robotiq_description/share/robotiq_description/meshes/collision/2f_85/robotiq_base.stl</uri>
            </mesh>
          </geometry>
          <max_contacts>10</max_contacts>
          <surface>
            <contact>
              <ode/>
            </contact>
            <bounce/>
            <friction>
              <torsional>
                <ode/>
              </torsional>
              <ode/>
            </friction>
          </surface>
        </collision>
        <visual name='left_robotiq_85_base_link_visual'>
          <pose>0 0 0 0 -0 0</pose>
          <geometry>
            <mesh>
              <scale>1 1 1</scale>
              <uri>file:///home/jjmczd/dual_v10/install/robotiq_description/share/robotiq_description/meshes/visual/2f_85/robotiq_base.dae</uri>
            </mesh>
          </geometry>
        </visual>
        <self_collide>0</self_collide>
        <enable_wind>0</enable_wind>
        <kinematic>0</kinematic>
      </link>
      <joint name='left_robotiq_85_left_inner_knuckle_joint' type='revolute'>
        <pose relative_to='left_robotiq_85_base_link'>0.0127 0 0.06142 0 -0 0</pose>
        <parent>left_robotiq_85_base_link</parent>
        <child>left_robotiq_85_left_inner_knuckle_link</child>
        <axis>
          <xyz>0 -1 0</xyz>
          <limit>
            <lower>-1e+16</lower>
            <upper>1e+16</upper>
          </limit>
          <dynamics>
            <spring_reference>0</spring_reference>
            <spring_stiffness>0</spring_stiffness>
          </dynamics>
        </axis>
      </joint>
      <link name='left_robotiq_85_left_inner_knuckle_link'>
        <pose relative_to='left_robotiq_85_left_inner_knuckle_joint'>0 0 0 0 -0 0</pose>
        <inertial>
          <pose>0.018977 0.00015 0.022471 0 -0 0</pose>
          <mass>0.0296938</mass>
          <inertia>
            <ixx>9.57136e-06</ixx>
            <ixy>0</ixy>
            <ixz>-3.93424e-06</ixz>
            <iyy>8.69056e-06</iyy>
            <iyz>0</iyz>
            <izz>8.19144e-06</izz>
          </inertia>
        </inertial>
        <collision name='left_robotiq_85_left_inner_knuckle_link_collision'>
          <pose>0 0 0 0 -0 0</pose>
          <geometry>
            <mesh>
              <scale>1 1 1</scale>
              <uri>file:///home/jjmczd/dual_v10/install/robotiq_description/share/robotiq_description/meshes/collision/2f_85/left_inner_knuckle.stl</uri>
            </mesh>
          </geometry>
          <max_contacts>10</max_contacts>
          <surface>
            <contact>
              <ode/>
            </contact>
            <bounce/>
            <friction>
              <torsional>
                <ode/>
              </torsional>
              <ode/>
            </friction>
          </surface>
        </collision>
        <visual name='left_robotiq_85_left_inner_knuckle_link_visual'>
          <pose>0 0 0 0 -0 0</pose>
          <geometry>
            <mesh>
              <scale>1 1 1</scale>
              <uri>file:///home/jjmczd/dual_v10/install/robotiq_description/share/robotiq_description/meshes/visual/2f_85/left_inner_knuckle.dae</uri>
            </mesh>
          </geometry>
        </visual>
        <self_collide>0</self_collide>
        <enable_wind>0</enable_wind>
        <kinematic>0</kinematic>
      </link>
      <joint name='left_robotiq_85_left_knuckle_joint' type='revolute'>
        <pose relative_to='left_robotiq_85_base_link'>0.030601 0 0.054905 0 -0 0</pose>
        <parent>left_robotiq_85_base_link</parent>
        <child>left_robotiq_85_left_knuckle_link</child>
        <axis>
          <xyz>0 -1 0</xyz>
          <limit>
            <lower>0</lower>
            <upper>0.8</upper>
            <effort>50</effort>
            <velocity>0.5</velocity>
          </limit>
          <dynamics>
            <spring_reference>0</spring_reference>
            <spring_stiffness>0</spring_stiffness>
          </dynamics>
        </axis>
      </joint>
      <link name='left_robotiq_85_left_knuckle_link'>
        <pose relative_to='left_robotiq_85_left_knuckle_joint'>0 0 0 0 -0 0</pose>
        <inertial>
          <pose>0.029387 -0.000551 0.011107 0 -0 0</pose>
          <mass>0.0564515</mass>
          <inertia>
            <ixx>1.67295e-05</ixx>
            <ixy>2.37618e-07</ixy>
            <ixz>-5.75738e-06</ixz>
            <iyy>2.21234e-05</iyy>
            <iyz>1.61032e-07</iyz>
            <izz>1.29013e-05</izz>
          </inertia>
        </inertial>
        <collision name='left_robotiq_85_left_knuckle_link_collision'>
          <pose>0 0 0 0 -0 0</pose>
          <geometry>
            <mesh>
              <scale>1 1 1</scale>
              <uri>file:///home/jjmczd/dual_v10/install/robotiq_description/share/robotiq_description/meshes/collision/2f_85/left_knuckle.stl</uri>
            </mesh>
          </geometry>
          <max_contacts>10</max_contacts>
          <surface>
            <contact>
              <ode/>
            </contact>
            <bounce/>
            <friction>
              <torsional>
                <ode/>
              </torsional>
              <ode/>
            </friction>
          </surface>
        </collision>
        <collision name='left_robotiq_85_left_knuckle_link_fixed_joint_lump__left_robotiq_85_left_finger_link_collision_1'>
          <pose>0.031526 0 -0.003763 0 -0 0</pose>
          <geometry>
            <mesh>
              <scale>1 1 1</scale>
              <uri>file:///home/jjmczd/dual_v10/install/robotiq_description/share/robotiq_description/meshes/collision/2f_85/left_finger.stl</uri>
            </mesh>
          </geometry>
          <max_contacts>10</max_contacts>
          <surface>
            <contact>
              <ode/>
            </contact>
            <bounce/>
            <friction>
              <torsional>
                <ode/>
              </torsional>
              <ode/>
            </friction>
          </surface>
        </collision>
        <visual name='left_robotiq_85_left_knuckle_link_visual'>
          <pose>0 0 0 0 -0 0</pose>
          <geometry>
            <mesh>
              <scale>1 1 1</scale>
              <uri>file:///home/jjmczd/dual_v10/install/robotiq_description/share/robotiq_description/meshes/visual/2f_85/left_knuckle.dae</uri>
            </mesh>
          </geometry>
        </visual>
        <visual name='left_robotiq_85_left_knuckle_link_fixed_joint_lump__left_robotiq_85_left_finger_link_visual_1'>
          <pose>0.031526 0 -0.003763 0 -0 0</pose>
          <geometry>
            <mesh>
              <scale>1 1 1</scale>
              <uri>file:///home/jjmczd/dual_v10/install/robotiq_description/share/robotiq_description/meshes/visual/2f_85/left_finger.dae</uri>
            </mesh>
          </geometry>
        </visual>
        <self_collide>0</self_collide>
        <enable_wind>0</enable_wind>
        <kinematic>0</kinematic>
      </link>
      <joint name='left_robotiq_85_left_finger_tip_joint' type='revolute'>
        <pose relative_to='left_robotiq_85_left_knuckle_link'>0.037158 0 0.043422 0 -0 0</pose>
        <parent>left_robotiq_85_left_knuckle_link</parent>
        <child>left_robotiq_85_left_finger_tip_link</child>
        <axis>
          <xyz>0 -1 0</xyz>
          <limit>
            <lower>-1e+16</lower>
            <upper>1e+16</upper>
          </limit>
          <dynamics>
            <spring_reference>0</spring_reference>
            <spring_stiffness>0</spring_stiffness>
          </dynamics>
        </axis>
      </joint>
      <link name='left_robotiq_85_left_finger_tip_link'>
        <pose relative_to='left_robotiq_85_left_finger_tip_joint'>0 0 0 0 -0 0</pose>
        <inertial>
          <pose>-0.014567 -0.0008 0.016497 0 -0 0</pose>
          <mass>0.0426859</mass>
          <inertia>
            <ixx>1.04815e-05</ixx>
            <ixy>0</ixy>
            <ixz>3.5232e-06</ixz>
            <iyy>1.19789e-05</iyy>
            <iyz>0</iyz>
            <izz>4.22784e-06</izz>
          </inertia>
        </inertial>
        <collision name='left_robotiq_85_left_finger_tip_link_collision'>
          <pose>0 0 0 0 -0 0</pose>
          <geometry>
            <mesh>
              <scale>1 1 1</scale>
              <uri>file:///home/jjmczd/dual_v10/install/robotiq_description/share/robotiq_description/meshes/collision/2f_85/left_finger_tip.stl</uri>
            </mesh>
          </geometry>
          <max_contacts>10</max_contacts>
          <surface>
            <contact>
              <ode/>
            </contact>
            <bounce/>
            <friction>
              <torsional>
                <ode/>
              </torsional>
              <ode/>
            </friction>
          </surface>
        </collision>
        <visual name='left_robotiq_85_left_finger_tip_link_visual'>
          <pose>0 0 0 0 -0 0</pose>
          <geometry>
            <mesh>
              <scale>1 1 1</scale>
              <uri>file:///home/jjmczd/dual_v10/install/robotiq_description/share/robotiq_description/meshes/visual/2f_85/left_finger_tip.dae</uri>
            </mesh>
          </geometry>
        </visual>
        <self_collide>0</self_collide>
        <enable_wind>0</enable_wind>
        <kinematic>0</kinematic>
      </link>
      <joint name='left_robotiq_85_right_inner_knuckle_joint' type='revolute'>
        <pose relative_to='left_robotiq_85_base_link'>-0.0127 0 0.06142 0 -0 0</pose>
        <parent>left_robotiq_85_base_link</parent>
        <child>left_robotiq_85_right_inner_knuckle_link</child>
        <axis>
          <xyz>0 -1 0</xyz>
          <limit>
            <lower>-1e+16</lower>
            <upper>1e+16</upper>
          </limit>
          <dynamics>
            <spring_reference>0</spring_reference>
            <spring_stiffness>0</spring_stiffness>
          </dynamics>
        </axis>
      </joint>
      <link name='left_robotiq_85_right_inner_knuckle_link'>
        <pose relative_to='left_robotiq_85_right_inner_knuckle_joint'>0 0 0 0 -0 0</pose>
        <inertial>
          <pose>-0.019268 5e-05 0.022222 0 -0 0</pose>
          <mass>0.0296938</mass>
          <inertia>
            <ixx>9.42456e-06</ixx>
            <ixy>0</ixy>
            <ixz>3.9636e-06</ixz>
            <iyy>8.69056e-06</iyy>
            <iyz>0</iyz>
            <izz>8.33824e-06</izz>
          </inertia>
        </inertial>
        <collision name='left_robotiq_85_right_inner_knuckle_link_collision'>
          <pose>0 0 0 0 -0 0</pose>
          <geometry>
            <mesh>
              <scale>1 1 1</scale>
              <uri>file:///home/jjmczd/dual_v10/install/robotiq_description/share/robotiq_description/meshes/collision/2f_85/right_inner_knuckle.stl</uri>
            </mesh>
          </geometry>
          <max_contacts>10</max_contacts>
          <surface>
            <contact>
              <ode/>
            </contact>
            <bounce/>
            <friction>
              <torsional>
                <ode/>
              </torsional>
              <ode/>
            </friction>
          </surface>
        </collision>
        <visual name='left_robotiq_85_right_inner_knuckle_link_visual'>
          <pose>0 0 0 0 -0 0</pose>
          <geometry>
            <mesh>
              <scale>1 1 1</scale>
              <uri>file:///home/jjmczd/dual_v10/install/robotiq_description/share/robotiq_description/meshes/visual/2f_85/right_inner_knuckle.dae</uri>
            </mesh>
          </geometry>
        </visual>
        <self_collide>0</self_collide>
        <enable_wind>0</enable_wind>
        <kinematic>0</kinematic>
      </link>
      <joint name='left_robotiq_85_right_knuckle_joint' type='revolute'>
        <pose relative_to='left_robotiq_85_base_link'>-0.030601 0 0.054905 0 -0 0</pose>
        <parent>left_robotiq_85_base_link</parent>
        <child>left_robotiq_85_right_knuckle_link</child>
        <axis>
          <xyz>0 -1 0</xyz>
          <limit>
            <lower>-0.8</lower>
            <upper>0</upper>
            <effort>50</effort>
            <velocity>0.5</velocity>
          </limit>
          <dynamics>
            <spring_reference>0</spring_reference>
            <spring_stiffness>0</spring_stiffness>
          </dynamics>
        </axis>
      </joint>
      <link name='left_robotiq_85_right_knuckle_link'>
        <pose relative_to='left_robotiq_85_right_knuckle_joint'>0 0 0 0 -0 0</pose>
        <inertial>
          <pose>-0.029387 4.5e-05 0.011107 0 -0 0</pose>
          <mass>0.0564515</mass>
          <inertia>
            <ixx>1.67196e-05</ixx>
            <ixy>-4.91092e-08</ixy>
            <ixz>5.75738e-06</ixz>
            <iyy>2.21234e-05</iyy>
            <iyz>3.3281e-08</iyz>
            <izz>1.28914e-05</izz>
          </inertia>
        </inertial>
        <collision name='left_robotiq_85_right_knuckle_link_collision'>
          <pose>0 0 0 0 -0 0</pose>
          <geometry>
            <mesh>
              <scale>1 1 1</scale>
              <uri>file:///home/jjmczd/dual_v10/install/robotiq_description/share/robotiq_description/meshes/collision/2f_85/right_knuckle.stl</uri>
            </mesh>
          </geometry>
          <max_contacts>10</max_contacts>
          <surface>
            <contact>
              <ode/>
            </contact>
            <bounce/>
            <friction>
              <torsional>
                <ode/>
              </torsional>
              <ode/>
            </friction>
          </surface>
        </collision>
        <collision name='left_robotiq_85_right_knuckle_link_fixed_joint_lump__left_robotiq_85_right_finger_link_collision_1'>
          <pose>-0.031526 0 -0.003763 0 -0 0</pose>
          <geometry>
            <mesh>
              <scale>1 1 1</scale>
              <uri>file:///home/jjmczd/dual_v10/install/robotiq_description/share/robotiq_description/meshes/collision/2f_85/right_finger.stl</uri>
            </mesh>
          </geometry>
          <max_contacts>10</max_contacts>
          <surface>
            <contact>
              <ode/>
            </contact>
            <bounce/>
            <friction>
              <torsional>
                <ode/>
              </torsional>
              <ode/>
            </friction>
          </surface>
        </collision>
        <visual name='left_robotiq_85_right_knuckle_link_visual'>
          <pose>0 0 0 0 -0 0</pose>
          <geometry>
            <mesh>
              <scale>1 1 1</scale>
              <uri>file:///home/jjmczd/dual_v10/install/robotiq_description/share/robotiq_description/meshes/visual/2f_85/right_knuckle.dae</uri>
            </mesh>
          </geometry>
        </visual>
        <visual name='left_robotiq_85_right_knuckle_link_fixed_joint_lump__left_robotiq_85_right_finger_link_visual_1'>
          <pose>-0.031526 0 -0.003763 0 -0 0</pose>
          <geometry>
            <mesh>
              <scale>1 1 1</scale>
              <uri>file:///home/jjmczd/dual_v10/install/robotiq_description/share/robotiq_description/meshes/visual/2f_85/right_finger.dae</uri>
            </mesh>
          </geometry>
        </visual>
        <self_collide>0</self_collide>
        <enable_wind>0</enable_wind>
        <kinematic>0</kinematic>
      </link>
      <joint name='left_robotiq_85_right_finger_tip_joint' type='revolute'>
        <pose relative_to='left_robotiq_85_right_knuckle_link'>-0.037158 0 0.043422 0 -0 0</pose>
        <parent>left_robotiq_85_right_knuckle_link</parent>
        <child>left_robotiq_85_right_finger_tip_link</child>
        <axis>
          <xyz>0 -1 0</xyz>
          <limit>
            <lower>-1e+16</lower>
            <upper>1e+16</upper>
          </limit>
          <dynamics>
            <spring_reference>0</spring_reference>
            <spring_stiffness>0</spring_stiffness>
          </dynamics>
        </axis>
      </joint>
      <link name='left_robotiq_85_right_finger_tip_link'>
        <pose relative_to='left_robotiq_85_right_finger_tip_joint'>0 0 0 0 -0 0</pose>
        <inertial>
          <pose>0.014567 5e-05 0.016497 0 -0 0</pose>
          <mass>0.0426859</mass>
          <inertia>
            <ixx>1.04815e-05</ixx>
            <ixy>0</ixy>
            <ixz>-3.5232e-06</ixz>
            <iyy>1.19789e-05</iyy>
            <iyz>0</iyz>
            <izz>4.22784e-06</izz>
          </inertia>
        </inertial>
        <collision name='left_robotiq_85_right_finger_tip_link_collision'>
          <pose>0 0 0 0 -0 0</pose>
          <geometry>
            <mesh>
              <scale>1 1 1</scale>
              <uri>file:///home/jjmczd/dual_v10/install/robotiq_description/share/robotiq_description/meshes/collision/2f_85/right_finger_tip.stl</uri>
            </mesh>
          </geometry>
          <max_contacts>10</max_contacts>
          <surface>
            <contact>
              <ode/>
            </contact>
            <bounce/>
            <friction>
              <torsional>
                <ode/>
              </torsional>
              <ode/>
            </friction>
          </surface>
        </collision>
        <visual name='left_robotiq_85_right_finger_tip_link_visual'>
          <pose>0 0 0 0 -0 0</pose>
          <geometry>
            <mesh>
              <scale>1 1 1</scale>
              <uri>file:///home/jjmczd/dual_v10/install/robotiq_description/share/robotiq_description/meshes/visual/2f_85/right_finger_tip.dae</uri>
            </mesh>
          </geometry>
        </visual>
        <self_collide>0</self_collide>
        <enable_wind>0</enable_wind>
        <kinematic>0</kinematic>
      </link>
      <joint name='right_shoulder_pan_joint' type='revolute'>
        <pose relative_to='dual_base'>-0.262064 -0.063173 0.544981 1.5711 0.785069 -0.784793</pose>
        <parent>dual_base</parent>
        <child>right_shoulder_link</child>
        <axis>
          <xyz>0 0 1</xyz>
          <limit>
            <lower>-6.28319</lower>
            <upper>6.28319</upper>
            <effort>150</effort>
            <velocity>3.14159</velocity>
          </limit>
          <dynamics>
            <damping>0</damping>
            <friction>0</friction>
            <spring_reference>0</spring_reference>
            <spring_stiffness>0</spring_stiffness>
          </dynamics>
        </axis>
      </joint>
      <link name='right_shoulder_link'>
        <pose relative_to='right_shoulder_pan_joint'>0 0 0 0 -0 0</pose>
        <inertial>
          <pose>0 0 0 0 -0 0</pose>
          <mass>3.7</mass>
          <inertia>
            <ixx>0.0149724</ixx>
            <ixy>0</ixy>
            <ixz>0</ixz>
            <iyy>0.0149724</iyy>
            <iyz>0</iyz>
            <izz>0.0104063</izz>
          </inertia>
        </inertial>
        <collision name='right_shoulder_link_collision'>
          <pose>0 0 0 0 -0 3.14159</pose>
          <geometry>
            <mesh>
              <scale>1 1 1</scale>
              <uri>file:///opt/ros/humble/share/ur_description/meshes/ur5/collision/shoulder.stl</uri>
            </mesh>
          </geometry>
          <max_contacts>10</max_contacts>
          <surface>
            <contact>
              <ode/>
            </contact>
            <bounce/>
            <friction>
              <torsional>
                <ode/>
              </torsional>
              <ode/>
            </friction>
          </surface>
        </collision>
        <visual name='right_shoulder_link_visual'>
          <pose>0 0 0 0 -0 3.14159</pose>
          <geometry>
            <mesh>
              <scale>1 1 1</scale>
              <uri>file:///opt/ros/humble/share/ur_description/meshes/ur5/visual/shoulder.dae</uri>
            </mesh>
          </geometry>
        </visual>
        <self_collide>0</self_collide>
        <enable_wind>0</enable_wind>
        <kinematic>0</kinematic>
      </link>
      <joint name='right_shoulder_lift_joint' type='revolute'>
        <pose relative_to='right_shoulder_link'>5.4e-05 0 0 1.57076 0 3e-05</pose>
        <parent>right_shoulder_link</parent>
        <child>right_upper_arm_link</child>
        <axis>
          <xyz>0 0 1</xyz>
          <limit>
            <lower>-6.28319</lower>
            <upper>6.28319</upper>
            <effort>150</effort>
            <velocity>3.14159</velocity>
          </limit>
          <dynamics>
            <damping>0</damping>
            <friction>0</friction>
            <spring_reference>0</spring_reference>
            <spring_stiffness>0</spring_stiffness>
          </dynamics>
        </axis>
      </joint>
      <link name='right_upper_arm_link'>
        <pose relative_to='right_shoulder_lift_joint'>0 0 0 0 -0 0</pose>
        <inertial>
          <pose>-0.2125 0 0.136 3.14159 1.57079 3.14159</pose>
          <mass>8.393</mass>
          <inertia>
            <ixx>0.133886</ixx>
            <ixy>0</ixy>
            <ixz>0</ixz>
            <iyy>0.133886</iyy>
            <iyz>0</iyz>
            <izz>0.0151074</izz>
          </inertia>
        </inertial>
        <collision name='right_upper_arm_link_collision'>
          <pose>0 0 0.13585 1.5708 0 -1.5708</pose>
          <geometry>
            <mesh>
              <scale>1 1 1</scale>
              <uri>file:///opt/ros/humble/share/ur_description/meshes/ur5/collision/upperarm.stl</uri>
            </mesh>
          </geometry>
          <max_contacts>10</max_contacts>
          <surface>
            <contact>
              <ode/>
            </contact>
            <bounce/>
            <friction>
              <torsional>
                <ode/>
              </torsional>
              <ode/>
            </friction>
          </surface>
        </collision>
        <visual name='right_upper_arm_link_visual'>
          <pose>0 0 0.13585 1.5708 0 -1.5708</pose>
          <geometry>
            <mesh>
              <scale>1 1 1</scale>
              <uri>file:///opt/ros/humble/share/ur_description/meshes/ur5/visual/upperarm.dae</uri>
            </mesh>
          </geometry>
        </visual>
        <self_collide>0</self_collide>
        <enable_wind>0</enable_wind>
        <kinematic>0</kinematic>
      </link>
      <joint name='right_elbow_joint' type='revolute'>
        <pose relative_to='right_upper_arm_link'>-0.425293 0 0 -0.000779 0.000992 -9.7e-05</pose>
        <parent>right_upper_arm_link</parent>
        <child>right_forearm_link</child>
        <axis>
          <xyz>0 0 1</xyz>
          <limit>
            <lower>-3.14159</lower>
            <upper>3.14159</upper>
            <effort>150</effort>
            <velocity>3.14159</velocity>
          </limit>
          <dynamics>
            <damping>0</damping>
            <friction>0</friction>
            <spring_reference>0</spring_reference>
            <spring_stiffness>0</spring_stiffness>
          </dynamics>
        </axis>
      </joint>
      <link name='right_forearm_link'>
        <pose relative_to='right_elbow_joint'>0 0 0 0 -0 0</pose>
        <inertial>
          <pose>-0.196125 0 0.0165 3.14159 1.57079 3.14159</pose>
          <mass>2.33</mass>
          <inertia>
            <ixx>0.0319715</ixx>
            <ixy>0</ixy>
            <ixz>0</ixz>
            <iyy>0.0319715</iyy>
            <iyz>0</iyz>
            <izz>0.004194</izz>
          </inertia>
        </inertial>
        <collision name='right_forearm_link_collision'>
          <pose>0 0 0.0165 1.5708 0 -1.5708</pose>
          <geometry>
            <mesh>
              <scale>1 1 1</scale>
              <uri>file:///opt/ros/humble/share/ur_description/meshes/ur5/collision/forearm.stl</uri>
            </mesh>
          </geometry>
          <max_contacts>10</max_contacts>
          <surface>
            <contact>
              <ode/>
            </contact>
            <bounce/>
            <friction>
              <torsional>
                <ode/>
              </torsional>
              <ode/>
            </friction>
          </surface>
        </collision>
        <visual name='right_forearm_link_visual'>
          <pose>0 0 0.0165 1.5708 0 -1.5708</pose>
          <geometry>
            <mesh>
              <scale>1 1 1</scale>
              <uri>file:///opt/ros/humble/share/ur_description/meshes/ur5/visual/forearm.dae</uri>
            </mesh>
          </geometry>
        </visual>
        <self_collide>0</self_collide>
        <enable_wind>0</enable_wind>
        <kinematic>0</kinematic>
      </link>
      <joint name='right_wrist_1_joint' type='revolute'>
        <pose relative_to='right_forearm_link'>-0.391949 -0.001524 0.110497 0.013795 0.001215 -8.6e-05</pose>
        <parent>right_forearm_link</parent>
        <child>right_wrist_1_link</child>
        <axis>
          <xyz>0 0 1</xyz>
          <limit>
            <lower>-6.28319</lower>
            <upper>6.28319</upper>
            <effort>28</effort>
            <velocity>3.14159</velocity>
          </limit>
          <dynamics>
            <damping>0</damping>
            <friction>0</friction>
            <spring_reference>0</spring_reference>
            <spring_stiffness>0</spring_stiffness>
          </dynamics>
        </axis>
      </joint>
      <link name='right_wrist_1_link'>
        <pose relative_to='right_wrist_1_joint'>0 0 0 0 -0 0</pose>
        <inertial>
          <pose>0 0 0 0 -0 0</pose>
          <mass>1.219</mass>
          <inertia>
            <ixx>0.00201389</ixx>
            <ixy>0</ixy>
            <ixz>0</ixz>
            <iyy>0.00201389</iyy>
            <iyz>0</iyz>
            <izz>0.0021942</izz>
          </inertia>
        </inertial>
        <collision name='right_wrist_1_link_collision'>
          <pose>0 0 -0.093 1.5708 -0 0</pose>
          <geometry>
            <mesh>
              <scale>1 1 1</scale>
              <uri>file:///opt/ros/humble/share/ur_description/meshes/ur5/collision/wrist1.stl</uri>
            </mesh>
          </geometry>
          <max_contacts>10</max_contacts>
          <surface>
            <contact>
              <ode/>
            </contact>
            <bounce/>
            <friction>
              <torsional>
                <ode/>
              </torsional>
              <ode/>
            </friction>
          </surface>
        </collision>
        <visual name='right_wrist_1_link_visual'>
          <pose>0 0 -0.093 1.5708 -0 0</pose>
          <geometry>
            <mesh>
              <scale>1 1 1</scale>
              <uri>file:///opt/ros/humble/share/ur_description/meshes/ur5/visual/wrist1.dae</uri>
            </mesh>
          </geometry>
        </visual>
        <self_collide>0</self_collide>
        <enable_wind>0</enable_wind>
        <kinematic>0</kinematic>
      </link>
      <joint name='right_wrist_2_joint' type='revolute'>
        <pose relative_to='right_wrist_1_link'>-0.000108 -0.094916 8.5e-05 1.5699 0 -5.1e-05</pose>
        <parent>right_wrist_1_link</parent>
        <child>right_wrist_2_link</child>
        <axis>
          <xyz>0 0 1</xyz>
          <limit>
            <lower>-6.28319</lower>
            <upper>6.28319</upper>
            <effort>28</effort>
            <velocity>3.14159</velocity>
          </limit>
          <dynamics>
            <damping>0</damping>
            <friction>0</friction>
            <spring_reference>0</spring_reference>
            <spring_stiffness>0</spring_stiffness>
          </dynamics>
        </axis>
      </joint>
      <link name='right_wrist_2_link'>
        <pose relative_to='right_wrist_2_joint'>0 0 0 0 -0 0</pose>
        <inertial>
          <pose>0 0 0 0 -0 0</pose>
          <mass>1.219</mass>
          <inertia>
            <ixx>0.00183104</ixx>
            <ixy>0</ixy>
            <ixz>0</ixz>
            <iyy>0.00183104</iyy>
            <iyz>0</iyz>
            <izz>0.0021942</izz>
          </inertia>
        </inertial>
        <collision name='right_wrist_2_link_collision'>
          <pose>0 0 -0.095 0 -0 0</pose>
          <geometry>
            <mesh>
              <scale>1 1 1</scale>
              <uri>file:///opt/ros/humble/share/ur_description/meshes/ur5/collision/wrist2.stl</uri>
            </mesh>
          </geometry>
          <max_contacts>10</max_contacts>
          <surface>
            <contact>
              <ode/>
            </contact>
            <bounce/>
            <friction>
              <torsional>
                <ode/>
              </torsional>
              <ode/>
            </friction>
          </surface>
        </collision>
        <visual name='right_wrist_2_link_visual'>
          <pose>0 0 -0.095 0 -0 0</pose>
          <geometry>
            <mesh>
              <scale>1 1 1</scale>
              <uri>file:///opt/ros/humble/share/ur_description/meshes/ur5/visual/wrist2.dae</uri>
            </mesh>
          </geometry>
        </visual>
        <self_collide>0</self_collide>
        <enable_wind>0</enable_wind>
        <kinematic>0</kinematic>
      </link>
      <joint name='right_wrist_3_joint' type='revolute'>
        <pose relative_to='right_wrist_2_link'>9.2e-05 0.082593 4.1e-05 -1.5703 0 -0.000115</pose>
        <parent>right_wrist_2_link</parent>
        <child>right_wrist_3_link</child>
        <axis>
          <xyz>0 0 1</xyz>
          <limit>
            <lower>-6.28319</lower>
            <upper>6.28319</upper>
            <effort>28</effort>
            <velocity>3.14159</velocity>
          </limit>
          <dynamics>
            <damping>0</damping>
            <friction>0</friction>
            <spring_reference>0</spring_reference>
            <spring_stiffness>0</spring_stiffness>
          </dynamics>
        </axis>
      </joint>
      <link name='right_wrist_3_link'>
        <pose relative_to='right_wrist_3_joint'>0 0 0 0 -0 0</pose>
        <inertial>
          <pose>-0 -0 0.027638 0 -0 0</pose>
          <mass>0.4879</mass>
          <inertia>
            <ixx>0.000904714</ixx>
            <ixy>3.67394e-22</ixy>
            <ixz>1e-06</ixz>
            <iyy>0.000907714</iyy>
            <iyz>-1e-06</iyz>
            <izz>0.000351117</izz>
          </inertia>
        </inertial>
        <collision name='right_wrist_3_link_collision'>
          <pose>0 0 -0.0818 1.5708 -0 0</pose>
          <geometry>
            <mesh>
              <scale>1 1 1</scale>
              <uri>file:///opt/ros/humble/share/ur_description/meshes/ur5/collision/wrist3.stl</uri>
            </mesh>
          </geometry>
          <max_contacts>10</max_contacts>
          <surface>
            <contact>
              <ode/>
            </contact>
            <bounce/>
            <friction>
              <torsional>
                <ode/>
              </torsional>
              <ode/>
            </friction>
          </surface>
        </collision>
        <collision name='right_wrist_3_link_fixed_joint_lump__right_ft300_mounting_plate_collision_1'>
          <pose>0 0 -0.004 0 -0 0</pose>
          <geometry>
            <mesh>
              <scale>1 1 1</scale>
              <uri>file:///home/jjmczd/dual_v10/install/robotiq_ft_sensor_description/share/robotiq_ft_sensor_description/meshes/collision/mountings/robotiq_ft300-G-062-COUPLING_G-50-4M6-1D6_20181119.STL</uri>
            </mesh>
          </geometry>
          <surface>
            <contact>
              <ode/>
            </contact>
            <friction>
              <ode/>
              <torsional>
                <ode/>
              </torsional>
            </friction>
            <bounce/>
          </surface>
          <max_contacts>10</max_contacts>
        </collision>
        <collision name='right_wrist_3_link_fixed_joint_lump__right_ft300_sensor_collision_2'>
          <pose>0 0 0.0375 3.14159 -0 3.14159</pose>
          <geometry>
            <mesh>
              <scale>1 1 1</scale>
              <uri>file:///home/jjmczd/dual_v10/install/robotiq_ft_sensor_description/share/robotiq_ft_sensor_description/meshes/collision/robotiq_ft300.STL</uri>
            </mesh>
          </geometry>
          <surface>
            <contact>
              <ode/>
            </contact>
            <friction>
              <ode/>
              <torsional>
                <ode/>
              </torsional>
            </friction>
            <bounce/>
          </surface>
          <max_contacts>10</max_contacts>
        </collision>
        <visual name='right_wrist_3_link_visual'>
          <pose>0 0 -0.0818 1.5708 -0 0</pose>
          <geometry>
            <mesh>
              <scale>1 1 1</scale>
              <uri>file:///opt/ros/humble/share/ur_description/meshes/ur5/visual/wrist3.dae</uri>
            </mesh>
          </geometry>
        </visual>
        <visual name='right_wrist_3_link_fixed_joint_lump__right_ft300_mounting_plate_visual_1'>
          <pose>0 0 -0.004 0 -0 0</pose>
          <geometry>
            <mesh>
              <scale>1 1 1</scale>
              <uri>file:///home/jjmczd/dual_v10/install/robotiq_ft_sensor_description/share/robotiq_ft_sensor_description/meshes/visual/mountings/robotiq_ft300-G-062-COUPLING_G-50-4M6-1D6_20181119.STL</uri>
            </mesh>
          </geometry>
          <material>
            <script>
              <name>Gazebo/Gray</name>
              <uri>file://media/materials/scripts/gazebo.material</uri>
            </script>
          </material>
        </visual>
        <visual name='right_wrist_3_link_fixed_joint_lump__right_ft300_sensor_visual_2'>
          <pose>0 0 0.0375 3.14159 -0 3.14159</pose>
          <geometry>
            <mesh>
              <scale>1 1 1</scale>
              <uri>file:///home/jjmczd/dual_v10/install/robotiq_ft_sensor_description/share/robotiq_ft_sensor_description/meshes/visual/robotiq_ft300.STL</uri>
            </mesh>
          </geometry>
          <material>
            <script>
              <name>Gazebo/DarkGrey</name>
              <uri>file://media/materials/scripts/gazebo.material</uri>
            </script>
          </material>
        </visual>
        <self_collide>0</self_collide>
        <enable_wind>0</enable_wind>
        <kinematic>0</kinematic>
      </link>
      <joint name='right_robotiq_85_base_joint' type='revolute'>
        <pose relative_to='right_wrist_3_link'>0 0 0.0375 0 -0 0</pose>
        <parent>right_wrist_3_link</parent>
        <child>right_robotiq_85_base_link</child>
        <axis>
          <limit>
            <lower>0</lower>
            <upper>0</upper>
          </limit>
          <dynamics>
            <damping>0</damping>
            <friction>0</friction>
            <spring_reference>0</spring_reference>
            <spring_stiffness>0</spring_stiffness>
          </dynamics>
          <xyz>0 0 1</xyz>
        </axis>
        <physics>
          <provide_feedback>1</provide_feedback>
          <ode>
            <limit>
              <cfm>0</cfm>
              <erp>0.2</erp>
            </limit>
            <provide_feedback>1</provide_feedback>
          </ode>
        </physics>
      </joint>
      <link name='right_robotiq_85_base_link'>
        <pose relative_to='right_robotiq_85_base_joint'>0 0 0 0 -0 0</pose>
        <inertial>
          <pose>0 2.3e-05 0.032323 0 -0 0</pose>
          <mass>0.663202</mass>
          <inertia>
            <ixx>0.000516178</ixx>
            <ixy>2.936e-08</ixy>
            <ixz>0</ixz>
            <iyy>0.000588022</iyy>
            <iyz>-3.2296e-07</iyz>
            <izz>0.000394628</izz>
          </inertia>
        </inertial>
        <collision name='right_robotiq_85_base_link_collision'>
          <pose>0 0 0 0 -0 0</pose>
          <geometry>
            <mesh>
              <scale>1 1 1</scale>
              <uri>file:///home/jjmczd/dual_v10/install/robotiq_description/share/robotiq_description/meshes/collision/2f_85/robotiq_base.stl</uri>
            </mesh>
          </geometry>
          <max_contacts>10</max_contacts>
          <surface>
            <contact>
              <ode/>
            </contact>
            <bounce/>
            <friction>
              <torsional>
                <ode/>
              </torsional>
              <ode/>
            </friction>
          </surface>
        </collision>
        <visual name='right_robotiq_85_base_link_visual'>
          <pose>0 0 0 0 -0 0</pose>
          <geometry>
            <mesh>
              <scale>1 1 1</scale>
              <uri>file:///home/jjmczd/dual_v10/install/robotiq_description/share/robotiq_description/meshes/visual/2f_85/robotiq_base.dae</uri>
            </mesh>
          </geometry>
        </visual>
        <self_collide>0</self_collide>
        <enable_wind>0</enable_wind>
        <kinematic>0</kinematic>
      </link>
      <joint name='right_robotiq_85_left_inner_knuckle_joint' type='revolute'>
        <pose relative_to='right_robotiq_85_base_link'>0.0127 0 0.06142 0 -0 0</pose>
        <parent>right_robotiq_85_base_link</parent>
        <child>right_robotiq_85_left_inner_knuckle_link</child>
        <axis>
          <xyz>0 -1 0</xyz>
          <limit>
            <lower>-1e+16</lower>
            <upper>1e+16</upper>
          </limit>
          <dynamics>
            <spring_reference>0</spring_reference>
            <spring_stiffness>0</spring_stiffness>
          </dynamics>
        </axis>
      </joint>
      <link name='right_robotiq_85_left_inner_knuckle_link'>
        <pose relative_to='right_robotiq_85_left_inner_knuckle_joint'>0 0 0 0 -0 0</pose>
        <inertial>
          <pose>0.018977 0.00015 0.022471 0 -0 0</pose>
          <mass>0.0296938</mass>
          <inertia>
            <ixx>9.57136e-06</ixx>
            <ixy>0</ixy>
            <ixz>-3.93424e-06</ixz>
            <iyy>8.69056e-06</iyy>
            <iyz>0</iyz>
            <izz>8.19144e-06</izz>
          </inertia>
        </inertial>
        <collision name='right_robotiq_85_left_inner_knuckle_link_collision'>
          <pose>0 0 0 0 -0 0</pose>
          <geometry>
            <mesh>
              <scale>1 1 1</scale>
              <uri>file:///home/jjmczd/dual_v10/install/robotiq_description/share/robotiq_description/meshes/collision/2f_85/left_inner_knuckle.stl</uri>
            </mesh>
          </geometry>
          <max_contacts>10</max_contacts>
          <surface>
            <contact>
              <ode/>
            </contact>
            <bounce/>
            <friction>
              <torsional>
                <ode/>
              </torsional>
              <ode/>
            </friction>
          </surface>
        </collision>
        <visual name='right_robotiq_85_left_inner_knuckle_link_visual'>
          <pose>0 0 0 0 -0 0</pose>
          <geometry>
            <mesh>
              <scale>1 1 1</scale>
              <uri>file:///home/jjmczd/dual_v10/install/robotiq_description/share/robotiq_description/meshes/visual/2f_85/left_inner_knuckle.dae</uri>
            </mesh>
          </geometry>
        </visual>
        <self_collide>0</self_collide>
        <enable_wind>0</enable_wind>
        <kinematic>0</kinematic>
      </link>
      <joint name='right_robotiq_85_left_knuckle_joint' type='revolute'>
        <pose relative_to='right_robotiq_85_base_link'>0.030601 0 0.054905 0 -0 0</pose>
        <parent>right_robotiq_85_base_link</parent>
        <child>right_robotiq_85_left_knuckle_link</child>
        <axis>
          <xyz>0 -1 0</xyz>
          <limit>
            <lower>0</lower>
            <upper>0.8</upper>
            <effort>50</effort>
            <velocity>0.5</velocity>
          </limit>
          <dynamics>
            <spring_reference>0</spring_reference>
            <spring_stiffness>0</spring_stiffness>
          </dynamics>
        </axis>
      </joint>
      <link name='right_robotiq_85_left_knuckle_link'>
        <pose relative_to='right_robotiq_85_left_knuckle_joint'>0 0 0 0 -0 0</pose>
        <inertial>
          <pose>0.029387 -0.000551 0.011107 0 -0 0</pose>
          <mass>0.0564515</mass>
          <inertia>
            <ixx>1.67295e-05</ixx>
            <ixy>2.37618e-07</ixy>
            <ixz>-5.75738e-06</ixz>
            <iyy>2.21234e-05</iyy>
            <iyz>1.61032e-07</iyz>
            <izz>1.29013e-05</izz>
          </inertia>
        </inertial>
        <collision name='right_robotiq_85_left_knuckle_link_collision'>
          <pose>0 0 0 0 -0 0</pose>
          <geometry>
            <mesh>
              <scale>1 1 1</scale>
              <uri>file:///home/jjmczd/dual_v10/install/robotiq_description/share/robotiq_description/meshes/collision/2f_85/left_knuckle.stl</uri>
            </mesh>
          </geometry>
          <max_contacts>10</max_contacts>
          <surface>
            <contact>
              <ode/>
            </contact>
            <bounce/>
            <friction>
              <torsional>
                <ode/>
              </torsional>
              <ode/>
            </friction>
          </surface>
        </collision>
        <collision name='right_robotiq_85_left_knuckle_link_fixed_joint_lump__right_robotiq_85_left_finger_link_collision_1'>
          <pose>0.031526 0 -0.003763 0 -0 0</pose>
          <geometry>
            <mesh>
              <scale>1 1 1</scale>
              <uri>file:///home/jjmczd/dual_v10/install/robotiq_description/share/robotiq_description/meshes/collision/2f_85/left_finger.stl</uri>
            </mesh>
          </geometry>
          <max_contacts>10</max_contacts>
          <surface>
            <contact>
              <ode/>
            </contact>
            <bounce/>
            <friction>
              <torsional>
                <ode/>
              </torsional>
              <ode/>
            </friction>
          </surface>
        </collision>
        <visual name='right_robotiq_85_left_knuckle_link_visual'>
          <pose>0 0 0 0 -0 0</pose>
          <geometry>
            <mesh>
              <scale>1 1 1</scale>
              <uri>file:///home/jjmczd/dual_v10/install/robotiq_description/share/robotiq_description/meshes/visual/2f_85/left_knuckle.dae</uri>
            </mesh>
          </geometry>
        </visual>
        <visual name='right_robotiq_85_left_knuckle_link_fixed_joint_lump__right_robotiq_85_left_finger_link_visual_1'>
          <pose>0.031526 0 -0.003763 0 -0 0</pose>
          <geometry>
            <mesh>
              <scale>1 1 1</scale>
              <uri>file:///home/jjmczd/dual_v10/install/robotiq_description/share/robotiq_description/meshes/visual/2f_85/left_finger.dae</uri>
            </mesh>
          </geometry>
        </visual>
        <self_collide>0</self_collide>
        <enable_wind>0</enable_wind>
        <kinematic>0</kinematic>
      </link>
      <joint name='right_robotiq_85_left_finger_tip_joint' type='revolute'>
        <pose relative_to='right_robotiq_85_left_knuckle_link'>0.037158 0 0.043422 0 -0 0</pose>
        <parent>right_robotiq_85_left_knuckle_link</parent>
        <child>right_robotiq_85_left_finger_tip_link</child>
        <axis>
          <xyz>0 -1 0</xyz>
          <limit>
            <lower>-1e+16</lower>
            <upper>1e+16</upper>
          </limit>
          <dynamics>
            <spring_reference>0</spring_reference>
            <spring_stiffness>0</spring_stiffness>
          </dynamics>
        </axis>
      </joint>
      <link name='right_robotiq_85_left_finger_tip_link'>
        <pose relative_to='right_robotiq_85_left_finger_tip_joint'>0 0 0 0 -0 0</pose>
        <inertial>
          <pose>-0.014567 -0.0008 0.016497 0 -0 0</pose>
          <mass>0.0426859</mass>
          <inertia>
            <ixx>1.04815e-05</ixx>
            <ixy>0</ixy>
            <ixz>3.5232e-06</ixz>
            <iyy>1.19789e-05</iyy>
            <iyz>0</iyz>
            <izz>4.22784e-06</izz>
          </inertia>
        </inertial>
        <collision name='right_robotiq_85_left_finger_tip_link_collision'>
          <pose>0 0 0 0 -0 0</pose>
          <geometry>
            <mesh>
              <scale>1 1 1</scale>
              <uri>file:///home/jjmczd/dual_v10/install/robotiq_description/share/robotiq_description/meshes/collision/2f_85/left_finger_tip.stl</uri>
            </mesh>
          </geometry>
          <max_contacts>10</max_contacts>
          <surface>
            <contact>
              <ode/>
            </contact>
            <bounce/>
            <friction>
              <torsional>
                <ode/>
              </torsional>
              <ode/>
            </friction>
          </surface>
        </collision>
        <visual name='right_robotiq_85_left_finger_tip_link_visual'>
          <pose>0 0 0 0 -0 0</pose>
          <geometry>
            <mesh>
              <scale>1 1 1</scale>
              <uri>file:///home/jjmczd/dual_v10/install/robotiq_description/share/robotiq_description/meshes/visual/2f_85/left_finger_tip.dae</uri>
            </mesh>
          </geometry>
        </visual>
        <self_collide>0</self_collide>
        <enable_wind>0</enable_wind>
        <kinematic>0</kinematic>
      </link>
      <joint name='right_robotiq_85_right_inner_knuckle_joint' type='revolute'>
        <pose relative_to='right_robotiq_85_base_link'>-0.0127 0 0.06142 0 -0 0</pose>
        <parent>right_robotiq_85_base_link</parent>
        <child>right_robotiq_85_right_inner_knuckle_link</child>
        <axis>
          <xyz>0 -1 0</xyz>
          <limit>
            <lower>-1e+16</lower>
            <upper>1e+16</upper>
          </limit>
          <dynamics>
            <spring_reference>0</spring_reference>
            <spring_stiffness>0</spring_stiffness>
          </dynamics>
        </axis>
      </joint>
      <link name='right_robotiq_85_right_inner_knuckle_link'>
        <pose relative_to='right_robotiq_85_right_inner_knuckle_joint'>0 0 0 0 -0 0</pose>
        <inertial>
          <pose>-0.019268 5e-05 0.022222 0 -0 0</pose>
          <mass>0.0296938</mass>
          <inertia>
            <ixx>9.42456e-06</ixx>
            <ixy>0</ixy>
            <ixz>3.9636e-06</ixz>
            <iyy>8.69056e-06</iyy>
            <iyz>0</iyz>
            <izz>8.33824e-06</izz>
          </inertia>
        </inertial>
        <collision name='right_robotiq_85_right_inner_knuckle_link_collision'>
          <pose>0 0 0 0 -0 0</pose>
          <geometry>
            <mesh>
              <scale>1 1 1</scale>
              <uri>file:///home/jjmczd/dual_v10/install/robotiq_description/share/robotiq_description/meshes/collision/2f_85/right_inner_knuckle.stl</uri>
            </mesh>
          </geometry>
          <max_contacts>10</max_contacts>
          <surface>
            <contact>
              <ode/>
            </contact>
            <bounce/>
            <friction>
              <torsional>
                <ode/>
              </torsional>
              <ode/>
            </friction>
          </surface>
        </collision>
        <visual name='right_robotiq_85_right_inner_knuckle_link_visual'>
          <pose>0 0 0 0 -0 0</pose>
          <geometry>
            <mesh>
              <scale>1 1 1</scale>
              <uri>file:///home/jjmczd/dual_v10/install/robotiq_description/share/robotiq_description/meshes/visual/2f_85/right_inner_knuckle.dae</uri>
            </mesh>
          </geometry>
        </visual>
        <self_collide>0</self_collide>
        <enable_wind>0</enable_wind>
        <kinematic>0</kinematic>
      </link>
      <joint name='right_robotiq_85_right_knuckle_joint' type='revolute'>
        <pose relative_to='right_robotiq_85_base_link'>-0.030601 0 0.054905 0 -0 0</pose>
        <parent>right_robotiq_85_base_link</parent>
        <child>right_robotiq_85_right_knuckle_link</child>
        <axis>
          <xyz>0 -1 0</xyz>
          <limit>
            <lower>-0.8</lower>
            <upper>0</upper>
            <effort>50</effort>
            <velocity>0.5</velocity>
          </limit>
          <dynamics>
            <spring_reference>0</spring_reference>
            <spring_stiffness>0</spring_stiffness>
          </dynamics>
        </axis>
      </joint>
      <link name='right_robotiq_85_right_knuckle_link'>
        <pose relative_to='right_robotiq_85_right_knuckle_joint'>0 0 0 0 -0 0</pose>
        <inertial>
          <pose>-0.029387 4.5e-05 0.011107 0 -0 0</pose>
          <mass>0.0564515</mass>
          <inertia>
            <ixx>1.67196e-05</ixx>
            <ixy>-4.91092e-08</ixy>
            <ixz>5.75738e-06</ixz>
            <iyy>2.21234e-05</iyy>
            <iyz>3.3281e-08</iyz>
            <izz>1.28914e-05</izz>
          </inertia>
        </inertial>
        <collision name='right_robotiq_85_right_knuckle_link_collision'>
          <pose>0 0 0 0 -0 0</pose>
          <geometry>
            <mesh>
              <scale>1 1 1</scale>
              <uri>file:///home/jjmczd/dual_v10/install/robotiq_description/share/robotiq_description/meshes/collision/2f_85/right_knuckle.stl</uri>
            </mesh>
          </geometry>
          <max_contacts>10</max_contacts>
          <surface>
            <contact>
              <ode/>
            </contact>
            <bounce/>
            <friction>
              <torsional>
                <ode/>
              </torsional>
              <ode/>
            </friction>
          </surface>
        </collision>
        <collision name='right_robotiq_85_right_knuckle_link_fixed_joint_lump__right_robotiq_85_right_finger_link_collision_1'>
          <pose>-0.031526 0 -0.003763 0 -0 0</pose>
          <geometry>
            <mesh>
              <scale>1 1 1</scale>
              <uri>file:///home/jjmczd/dual_v10/install/robotiq_description/share/robotiq_description/meshes/collision/2f_85/right_finger.stl</uri>
            </mesh>
          </geometry>
          <max_contacts>10</max_contacts>
          <surface>
            <contact>
              <ode/>
            </contact>
            <bounce/>
            <friction>
              <torsional>
                <ode/>
              </torsional>
              <ode/>
            </friction>
          </surface>
        </collision>
        <visual name='right_robotiq_85_right_knuckle_link_visual'>
          <pose>0 0 0 0 -0 0</pose>
          <geometry>
            <mesh>
              <scale>1 1 1</scale>
              <uri>file:///home/jjmczd/dual_v10/install/robotiq_description/share/robotiq_description/meshes/visual/2f_85/right_knuckle.dae</uri>
            </mesh>
          </geometry>
        </visual>
        <visual name='right_robotiq_85_right_knuckle_link_fixed_joint_lump__right_robotiq_85_right_finger_link_visual_1'>
          <pose>-0.031526 0 -0.003763 0 -0 0</pose>
          <geometry>
            <mesh>
              <scale>1 1 1</scale>
              <uri>file:///home/jjmczd/dual_v10/install/robotiq_description/share/robotiq_description/meshes/visual/2f_85/right_finger.dae</uri>
            </mesh>
          </geometry>
        </visual>
        <self_collide>0</self_collide>
        <enable_wind>0</enable_wind>
        <kinematic>0</kinematic>
      </link>
      <joint name='right_robotiq_85_right_finger_tip_joint' type='revolute'>
        <pose relative_to='right_robotiq_85_right_knuckle_link'>-0.037158 0 0.043422 0 -0 0</pose>
        <parent>right_robotiq_85_right_knuckle_link</parent>
        <child>right_robotiq_85_right_finger_tip_link</child>
        <axis>
          <xyz>0 -1 0</xyz>
          <limit>
            <lower>-1e+16</lower>
            <upper>1e+16</upper>
          </limit>
          <dynamics>
            <spring_reference>0</spring_reference>
            <spring_stiffness>0</spring_stiffness>
          </dynamics>
        </axis>
      </joint>
      <link name='right_robotiq_85_right_finger_tip_link'>
        <pose relative_to='right_robotiq_85_right_finger_tip_joint'>0 0 0 0 -0 0</pose>
        <inertial>
          <pose>0.014567 5e-05 0.016497 0 -0 0</pose>
          <mass>0.0426859</mass>
          <inertia>
            <ixx>1.04815e-05</ixx>
            <ixy>0</ixy>
            <ixz>-3.5232e-06</ixz>
            <iyy>1.19789e-05</iyy>
            <iyz>0</iyz>
            <izz>4.22784e-06</izz>
          </inertia>
        </inertial>
        <collision name='right_robotiq_85_right_finger_tip_link_collision'>
          <pose>0 0 0 0 -0 0</pose>
          <geometry>
            <mesh>
              <scale>1 1 1</scale>
              <uri>file:///home/jjmczd/dual_v10/install/robotiq_description/share/robotiq_description/meshes/collision/2f_85/right_finger_tip.stl</uri>
            </mesh>
          </geometry>
          <max_contacts>10</max_contacts>
          <surface>
            <contact>
              <ode/>
            </contact>
            <bounce/>
            <friction>
              <torsional>
                <ode/>
              </torsional>
              <ode/>
            </friction>
          </surface>
        </collision>
        <visual name='right_robotiq_85_right_finger_tip_link_visual'>
          <pose>0 0 0 0 -0 0</pose>
          <geometry>
            <mesh>
              <scale>1 1 1</scale>
              <uri>file:///home/jjmczd/dual_v10/install/robotiq_description/share/robotiq_description/meshes/visual/2f_85/right_finger_tip.dae</uri>
            </mesh>
          </geometry>
        </visual>
        <self_collide>0</self_collide>
        <enable_wind>0</enable_wind>
        <kinematic>0</kinematic>
      </link>
      <plugin name='left_gazebo_ros_ft_sensor' filename='libgazebo_ros_ft_sensor.so'>
        <ros>
          <namespace>/left_robotiq_ft300</namespace>
        </ros>
        <joint_name>left_robotiq_85_base_joint</joint_name>
        <update_rate>50</update_rate>
        <gaussian_noise>0.01</gaussian_noise>
      </plugin>
      <plugin name='right_gazebo_ros_ft_sensor' filename='libgazebo_ros_ft_sensor.so'>
        <ros>
          <namespace>/right_robotiq_ft300</namespace>
        </ros>
        <joint_name>right_robotiq_85_base_joint</joint_name>
        <update_rate>50</update_rate>
        <gaussian_noise>0.01</gaussian_noise>
      </plugin>
      <plugin name='gazebo_ros2_control' filename='libgazebo_ros2_control.so'>
        <parameters>/home/jjmczd/dual_v10/install/dual_description/share/dual_description/config/controllers.yaml</parameters>
      </plugin>
      <static>0</static>
      <plugin name='gazebo_grasp_fix' filename='libgazebo_grasp_fix.so'>
        <arm>
          <arm_name>left_robotiq_85_gripper_arm</arm_name>
          <palm_link>left_wrist_3_link</palm_link>
          <gripper_link>left_robotiq_85_left_finger_tip_link</gripper_link>
          <gripper_link>left_robotiq_85_right_finger_tip_link</gripper_link>
          <gripper_link>left_robotiq_85_left_knuckle_link</gripper_link>
          <gripper_link>left_robotiq_85_right_knuckle_link</gripper_link>
          <gripper_link>left_robotiq_85_left_inner_knuckle_link</gripper_link>
          <gripper_link>left_robotiq_85_right_inner_knuckle_link</gripper_link>
        </arm>
        <arm>
          <arm_name>right_robotiq_85_gripper_arm</arm_name>
          <palm_link>right_wrist_3_link</palm_link>
          <gripper_link>right_robotiq_85_left_finger_tip_link</gripper_link>
          <gripper_link>right_robotiq_85_right_finger_tip_link</gripper_link>
          <gripper_link>right_robotiq_85_left_knuckle_link</gripper_link>
          <gripper_link>right_robotiq_85_right_knuckle_link</gripper_link>
          <gripper_link>right_robotiq_85_left_inner_knuckle_link</gripper_link>
          <gripper_link>right_robotiq_85_right_inner_knuckle_link</gripper_link>
        </arm>
        <forces_angle_tolerance>150</forces_angle_tolerance>
        <update_rate>30</update_rate>
        <grip_count_threshold>1</grip_count_threshold>
        <max_grip_count>2</max_grip_count>
        <release_tolerance>0.01</release_tolerance>
        <disable_collisions_on_attach>0</disable_collisions_on_attach>
        <contact_topic>__default_topic__</contact_topic>
      </plugin>
      <pose>0 0 0 0 -0 0</pose>
    </model>
    <model name='small_bottle'>
      <link name='link_1'>
        <inertial>
          <mass>1</mass>
          <inertia>
            <ixx>0.166667</ixx>
            <ixy>0</ixy>
            <ixz>0</ixz>
            <iyy>0.166667</iyy>
            <iyz>0</iyz>
            <izz>0.166667</izz>
          </inertia>
          <pose>0 0 0 0 -0 0</pose>
        </inertial>
        <pose>0 0 0 0 -0 0</pose>
        <gravity>1</gravity>
        <self_collide>0</self_collide>
        <kinematic>0</kinematic>
        <enable_wind>0</enable_wind>
        <visual name='visual'>
          <pose>0 0 0 0 -0 0</pose>
          <geometry>
            <mesh>
              <uri>/home/jjmczd/dual_v10/src/mtc_pour-ros2/meshes/small_bottle.stl</uri>
              <scale>1 1 1</scale>
            </mesh>
          </geometry>
          <material>
            <lighting>1</lighting>
            <script>
              <uri>file://media/materials/scripts/gazebo.material</uri>
              <name>Gazebo/Grey</name>
            </script>
            <shader type='pixel'>
              <normal_map>__default__</normal_map>
            </shader>
            <ambient>0.3 0.3 0.3 1</ambient>
            <diffuse>0.7 0.7 0.7 1</diffuse>
            <specular>0.01 0.01 0.01 1</specular>
            <emissive>0 0 0 1</emissive>
          </material>
          <transparency>0</transparency>
          <cast_shadows>1</cast_shadows>
        </visual>
        <collision name='collision'>
          <laser_retro>0</laser_retro>
          <max_contacts>10</max_contacts>
          <pose>0 0 0 0 -0 0</pose>
          <geometry>
            <mesh>
              <uri>/home/jjmczd/dual_v10/src/mtc_pour-ros2/meshes/small_bottle.stl</uri>
              <scale>1 1 1</scale>
            </mesh>
          </geometry>
          <surface>
            <friction>
              <ode>
                <mu>1</mu>
                <mu2>1</mu2>
                <fdir1>0 0 0</fdir1>
                <slip1>0</slip1>
                <slip2>0</slip2>
              </ode>
              <torsional>
                <coefficient>1</coefficient>
                <patch_radius>0</patch_radius>
                <surface_radius>0</surface_radius>
                <use_patch_radius>1</use_patch_radius>
                <ode>
                  <slip>0</slip>
                </ode>
              </torsional>
            </friction>
            <bounce>
              <restitution_coefficient>0</restitution_coefficient>
              <threshold>1e+06</threshold>
            </bounce>
            <contact>
              <collide_without_contact>0</collide_without_contact>
              <collide_without_contact_bitmask>1</collide_without_contact_bitmask>
              <collide_bitmask>1</collide_bitmask>
              <ode>
                <soft_cfm>0</soft_cfm>
                <soft_erp>0.2</soft_erp>
                <kp>1e+13</kp>
                <kd>1</kd>
                <max_vel>0.01</max_vel>
                <min_depth>0</min_depth>
              </ode>
              <bullet>
                <split_impulse>1</split_impulse>
                <split_impulse_penetration_threshold>-0.01</split_impulse_penetration_threshold>
                <soft_cfm>0</soft_cfm>
                <soft_erp>0.2</soft_erp>
                <kp>1e+13</kp>
                <kd>1</kd>
              </bullet>
            </contact>
          </surface>
        </collision>
      </link>
      <static>0</static>
      <allow_auto_disable>1</allow_auto_disable>
      <pose>0.275875 -0.602774 0 0 -0 0</pose>
    </model>
    <model name='glass'>
      <link name='link_4'>
        <inertial>
          <mass>1</mass>
          <inertia>
            <ixx>0.166667</ixx>
            <ixy>0</ixy>
            <ixz>0</ixz>
            <iyy>0.166667</iyy>
            <iyz>0</iyz>
            <izz>0.166667</izz>
          </inertia>
          <pose>0 0 0 0 -0 0</pose>
        </inertial>
        <pose>0 0 0 0 -0 0</pose>
        <gravity>1</gravity>
        <self_collide>0</self_collide>
        <kinematic>0</kinematic>
        <enable_wind>0</enable_wind>
        <visual name='visual'>
          <pose>0 0 0 0 -0 0</pose>
          <geometry>
            <mesh>
              <uri>/home/jjmczd/dual_v10/src/mtc_pour-ros2/meshes/glass.stl</uri>
              <scale>1 1 1</scale>
            </mesh>
          </geometry>
          <material>
            <lighting>1</lighting>
            <script>
              <uri>file://media/materials/scripts/gazebo.material</uri>
              <name>Gazebo/Grey</name>
            </script>
            <shader type='pixel'>
              <normal_map>__default__</normal_map>
            </shader>
            <ambient>0.3 0.3 0.3 1</ambient>
            <diffuse>0.7 0.7 0.7 1</diffuse>
            <specular>0.01 0.01 0.01 1</specular>
            <emissive>0 0 0 1</emissive>
          </material>
          <transparency>0</transparency>
          <cast_shadows>1</cast_shadows>
        </visual>
        <collision name='collision'>
          <laser_retro>0</laser_retro>
          <max_contacts>10</max_contacts>
          <pose>0 0 0 0 -0 0</pose>
          <geometry>
            <mesh>
              <uri>/home/jjmczd/dual_v10/src/mtc_pour-ros2/meshes/glass.stl</uri>
              <scale>1 1 1</scale>
            </mesh>
          </geometry>
          <surface>
            <friction>
              <ode>
                <mu>1</mu>
                <mu2>1</mu2>
                <fdir1>0 0 0</fdir1>
                <slip1>0</slip1>
                <slip2>0</slip2>
              </ode>
              <torsional>
                <coefficient>1</coefficient>
                <patch_radius>0</patch_radius>
                <surface_radius>0</surface_radius>
                <use_patch_radius>1</use_patch_radius>
                <ode>
                  <slip>0</slip>
                </ode>
              </torsional>
            </friction>
            <bounce>
              <restitution_coefficient>0</restitution_coefficient>
              <threshold>1e+06</threshold>
            </bounce>
            <contact>
              <collide_without_contact>0</collide_without_contact>
              <collide_without_contact_bitmask>1</collide_without_contact_bitmask>
              <collide_bitmask>1</collide_bitmask>
              <ode>
                <soft_cfm>0</soft_cfm>
                <soft_erp>0.2</soft_erp>
                <kp>1e+13</kp>
                <kd>1</kd>
                <max_vel>0.01</max_vel>
                <min_depth>0</min_depth>
              </ode>
              <bullet>
                <split_impulse>1</split_impulse>
                <split_impulse_penetration_threshold>-0.01</split_impulse_penetration_threshold>
                <soft_cfm>0</soft_cfm>
                <soft_erp>0.2</soft_erp>
                <kp>1e+13</kp>
                <kd>1</kd>
              </bullet>
            </contact>
          </surface>
        </collision>
      </link>
      <static>0</static>
      <allow_auto_disable>1</allow_auto_disable>
      <pose>-0.050142 -0.670839 0 0 -0 0</pose>
    </model>
  </world>
</sdf>
